Workbook

Sheet Mode d'emploi
A1: Grille de scoring Project Finance — expliquée
A2: Pour le chargé d'affaires : quelle situation choisir pour chaque sous-critère, avec un exemple par situation. Dossiers et exemples fictifs.
A4: Comment la note est construite | B4: 1. Routage (régime de revenus, secteur, phase) → seuils DSCR et poids. 2. Noyau financier D7 (N1 à N6). 3. Grille qualitative D1 à D9 (25 sous-critères). 4. Score sur 100 → note de 1 à 10. 5. Plafonds et verrous : la note approuvée est le minimum.
A5: Ce que fait le chargé d'affaires | B5: Pour chaque sous-critère, il lit la question « Ce qu'on évalue », vérifie les pièces listées, puis choisit dans l'outil la situation qui décrit le mieux le dossier. La note (100, 80, 50 ou 20) s'en déduit.
A6: Règle de choix | B6: Choisir la situation qui décrit le dossier AUJOURD'HUI, preuves à l'appui. En cas d'hésitation entre deux niveaux, retenir le plus prudent et l'expliquer en commentaire. Une promesse non signée vaut la situation sans la promesse.
A7: Info. insuffisante | B7: À choisir quand la pièce qui permettrait de trancher n'est pas au dossier. Elle compte 20, rend la note provisoire et exige un commentaire indiquant la pièce attendue.
A8: Critique | B8: Un commentaire est obligatoire : constat, pièce, et ce qui permettrait de remonter le niveau.
A9: Onglets | B9: Grille (D1 à D9) · Noyau N1-N6 · Variantes sectorielles (D2.1, D4.1, D4.3, D5.2 par secteur) · Routage et seuils (calculateur) · Plafonds · Verrous · Conversion (calculateur) · Exemple de calcul · Glossaire · Paramètres.
A10: Légende | B10: Cellules bleues : valeurs modifiables (paramètres, calculateurs). Les notes de la grille et les calculs sont des formules qui lisent l'onglet Paramètres.
A12: Niveau | B12: Note | C12: Signification générale
A13: Très favorable | B13: =Paramètres!$B$5 -> 100 | C13: Meilleure pratique du marché, établie par des pièces signées ou indépendantes.
A14: Favorable | B14: =Paramètres!$B$6 -> 80 | C14: Bon niveau, avec une limite mineure identifiée.
A15: Vigilance | B15: =Paramètres!$B$7 -> 50 | C15: Faiblesse réelle qui demande un mitigant ou une condition.
A16: Critique | B16: =Paramètres!$B$8 -> 20 | C16: Point de rupture possible ; souvent lié à un plafond ou à un verrou.
A17: Info. insuffisante | B17: =Paramètres!$B$9 -> 20 | C17: La pièce manque : on ne peut pas juger.

Sheet Grille
A1: Grille qualitative D1 à D9 — situations et exemples
A2: Une ligne par situation. Colonne « Dans l'outil » : texte exact de la liste déroulante. Les variantes par secteur de D2.1, D4.1, D4.3 et D5.2 sont dans l'onglet Variantes sectorielles.
A4: Domaine | B4: Poids P1 / P2 / P3 | C4: Clé | D4: Sous-critère | E4: Poids dans le domaine | F4: Ce qu'on évalue | G4: Pièces à vérifier | H4: Niveau | I4: Note | J4: Dans l'outil (liste) | K4: Exemple : on choisit ce niveau quand…
A5: D1 — Sponsors et actionnariat | B5: 10 % / 8 % / 5 % | C5: D1.1 | D5: Capacité financière du sponsor | E5: 0.4 | F5: La solidité financière du sponsor : peut-il apporter l'argent promis, et plus si le projet dérape ? | G5: États financiers des 3 derniers exercices, notation (interne ou agence), lettre d'engagement de fonds propres, liste des autres projets en cours. | H5: Très favorable | I5: =Paramètres!$B$5 -> 100 | J5: Très favorable — Sponsor noté ≥ BBB, fonds propres disponibles > 3 × l'appel restant | K5: Énergéticien international noté BBB+, 2 milliards MAD de fonds propres, il lui reste 150 MMAD à apporter.
H6: Favorable | I6: =Paramètres!$B$6 -> 80 | J6: Favorable — Sponsor solide, capacité couvrant l'appel restant avec marge | K6: Groupe industriel marocain solide, trésorerie de 400 MMAD pour 120 MMAD restant à apporter.
H7: Vigilance | I7: =Paramètres!$B$7 -> 50 | J7: Vigilance — Capacité juste suffisante ou dépendante d'autres projets | K7: Promoteur qui finance trois projets en même temps : sa trésorerie couvre l'appel restant de justesse.
H8: Critique | I8: =Paramètres!$B$8 -> 20 | J8: Critique — Capacité insuffisante ou sponsor en difficulté financière | K8: Sponsor en pertes depuis deux ans, fonds propres négatifs, ou en restructuration de sa propre dette.
H9: Info. insuffisante | I9: =Paramètres!$B$9 -> 20 | J9: Info. insuffisante | K9: États financiers non remis ou datant de plus de 18 mois.
A10: D1 — Sponsors et actionnariat | B10: 10 % / 8 % / 5 % | C10: D1.2 | D10: Obligation juridique de soutien | E10: 0.35 | F10: Ce que le sponsor s'est engagé juridiquement à faire, pas seulement ce qu'il pourrait faire. | G10: Contrat d'apport (equity contribution agreement), garantie de dépassement de coûts (cost overrun), garantie de bonne fin (completion guarantee). | H10: Très favorable | I10: =Paramètres!$B$5 -> 100 | J10: Très favorable — Engagements signés : fonds propres, dépassement, garanties de complétion | K10: Contrat d'apport signé, garantie de dépassement de 10 % du CAPEX et garantie de bonne fin jusqu'à la réception.
H11: Favorable | I11: =Paramètres!$B$6 -> 80 | J11: Favorable — Engagement de fonds propres signé, dépassement partiellement couvert | K11: Apport de fonds propres signé ; dépassement couvert à 5 % seulement.
H12: Vigilance | I12: =Paramètres!$B$7 -> 50 | J12: Vigilance — Lettre de confort ou engagement non encore signé | K12: Simple lettre de confort (« nous soutiendrons le projet ») sans engagement chiffré.
H13: Critique | I13: =Paramètres!$B$8 -> 20 | J13: Critique — Aucun engagement juridique du sponsor | K13: Aucun document : le sponsor peut se retirer sans pénalité.
H14: Info. insuffisante | I14: =Paramètres!$B$9 -> 20 | J14: Info. insuffisante | K14: Engagements annoncés mais aucun projet de contrat communiqué.
A15: D1 — Sponsors et actionnariat | B15: 10 % / 8 % / 5 % | C15: D1.3 | D15: Structure actionnariale et gouvernance | E15: 0.25 | F15: Qui détient la société de projet (SPV), comment elle est gouvernée, et le risque de départ d'un actionnaire. | G15: Organigramme actionnarial jusqu'aux bénéficiaires effectifs, pacte d'actionnaires, clauses de cession (lock-up). | H15: Très favorable | I15: =Paramètres!$B$5 -> 100 | J15: Très favorable — Actionnariat stable, pacte signé, gouvernance de la SPV documentée | K15: Deux actionnaires stables (60/40), pacte signé, interdiction de céder avant la réception, bénéficiaires connus.
H16: Favorable | I16: =Paramètres!$B$6 -> 80 | J16: Favorable — Actionnariat stable, pacte en cours de finalisation | K16: Actionnariat stable, pacte en cours de signature, bénéficiaires connus.
H17: Vigilance | I17: =Paramètres!$B$7 -> 50 | J17: Vigilance — Actionnariat dispersé ou clauses de sortie précoces | K17: Cinq actionnaires minoritaires, ou un fonds qui peut sortir dès la 3e année.
H18: Critique | I18: =Paramètres!$B$8 -> 20 | J18: Critique — Actionnariat instable, conflit ou bénéficiaire effectif non établi | K18: Conflit entre actionnaires, ou bénéficiaire effectif non identifié (exigence KYC / LBC-FT).
H19: Info. insuffisante | I19: =Paramètres!$B$9 -> 20 | J19: Info. insuffisante | K19: Organigramme incomplet, bénéficiaires effectifs non documentés.
A20: D2 — Projet, site, technologie | B20: 10 % / 7 % / 5 % | C20: D2.1 | D20: Technologie et performance | E20: 0.35 | F20: La technologie fonctionne-t-elle comme prévu, à cette taille ? (variante par secteur dans l'onglet Variantes sectorielles) | G20: Rapport de l'ingénieur indépendant, références du fournisseur, garanties de performance. | H20: Très favorable | I20: =Paramètres!$B$5 -> 100 | J20: Très favorable — Technologie éprouvée, références nombreuses et comparables | K20: Station de dessalement par osmose inverse, procédé utilisé dans 30 usines de taille comparable.
H21: Favorable | I21: =Paramètres!$B$6 -> 80 | J21: Favorable — Technologie éprouvée, références moins nombreuses ou plus petites | K21: Technologie éprouvée mais le fournisseur n'a que 2 références de cette taille.
H22: Vigilance | I22: =Paramètres!$B$7 -> 50 | J22: Vigilance — Technologie récente ou extrapolée à une taille supérieure | K22: Unité de nouvelle génération extrapolée au double de la taille des références existantes.
H23: Critique | I23: =Paramètres!$B$8 -> 20 | J23: Critique — Technologie non éprouvée à cette échelle | K23: Premier déploiement industriel d'un procédé testé seulement en pilote.
H24: Info. insuffisante | I24: =Paramètres!$B$9 -> 20 | J24: Info. insuffisante | K24: Pas de rapport technique indépendant.
A25: D2 — Projet, site, technologie | B25: 10 % / 7 % / 5 % | C25: D2.2 | D25: Site, foncier physique et accès | E25: 0.4 | F25: Le terrain est-il acquis, sain et accessible (routes, réseau électrique, eau) ? | G25: Titre foncier ou contrat de location, études géotechniques, autorisations de raccordement. | H25: Très favorable | I25: =Paramètres!$B$5 -> 100 | J25: Très favorable — Foncier sécurisé, études de sol faites, accès et réseaux disponibles | K25: Terrain acquis et immatriculé, sol étudié, poste électrique à 2 km avec accord de raccordement.
H26: Favorable | I26: =Paramètres!$B$6 -> 80 | J26: Favorable — Foncier sécurisé, études ou raccordements encore à finaliser | K26: Terrain sécurisé par bail long, raccordement électrique accordé mais travaux non commencés.
H27: Vigilance | I27: =Paramètres!$B$7 -> 50 | J27: Vigilance — Foncier ou accès en cours d'obtention, contraintes de site identifiées | K27: Achat du terrain en cours, ou piste d'accès à construire par une commune.
H28: Critique | I28: =Paramètres!$B$8 -> 20 | J28: Critique — Foncier non sécurisé ou contrainte de site non résolue | K28: Terrain non acquis ou litige foncier en cours (voir aussi le verrou B4).
H29: Info. insuffisante | I29: =Paramètres!$B$9 -> 20 | J29: Info. insuffisante | K29: Statut foncier non communiqué.
A30: D2 — Projet, site, technologie | B30: 10 % / 7 % / 5 % | C30: D2.3 | D30: Planning et complexité d'exécution | E30: 0.25 | F30: Le calendrier est-il réaliste et le chantier maîtrisable ? | G30: Planning détaillé, chemin critique, avis de l'ingénieur indépendant. | H30: Très favorable | I30: =Paramètres!$B$5 -> 100 | J30: Très favorable — Planning réaliste avec marge, chantier simple et répétitif | K30: Parc solaire de 18 mois avec 3 mois de marge, opérations répétitives.
H31: Favorable | I31: =Paramètres!$B$6 -> 80 | J31: Favorable — Planning tenable, quelques interfaces critiques identifiées | K31: Planning tenable ; dépend de la livraison d'un transformateur dans les délais.
H32: Vigilance | I32: =Paramètres!$B$7 -> 50 | J32: Vigilance — Planning tendu ou chemin critique dépendant de tiers | K32: Planning serré qui dépend d'un tiers (raccordement par l'opérateur public, permis en attente).
H33: Critique | I33: =Paramètres!$B$8 -> 20 | J33: Critique — Planning irréaliste ou complexité non maîtrisée | K33: Planning de 12 mois pour un chantier que les experts estiment à 24 mois.
H34: Info. insuffisante | I34: =Paramètres!$B$9 -> 20 | J34: Info. insuffisante | K34: Aucun planning détaillé remis.
A35: D3 — Construction et achèvement | B35: 20 % / 8 % / 0 % | C35: D3.1 | D35: Contrat EPC et constructeur | E35: 0.4 | F35: Le contrat de construction (EPC) protège-t-il la SPV contre les retards et dépassements ? | G35: Contrat EPC : prix forfaitaire, date garantie, pénalités de retard et de performance, garanties bancaires du constructeur. | H35: Très favorable | I35: =Paramètres!$B$5 -> 100 | J35: Très favorable — EPC clé-en-main forfaitaire, constructeur de premier rang, pénalités ≥ 15 % | K35: EPC clé-en-main à prix fixe, constructeur international, pénalités de retard jusqu'à 15 % du contrat.
H36: Favorable | I36: =Paramètres!$B$6 -> 80 | J36: Favorable — EPC forfaitaire, pénalités ou garanties légèrement en retrait | K36: EPC forfaitaire mais pénalités plafonnées à 10 %.
H37: Vigilance | I37: =Paramètres!$B$7 -> 50 | J37: Vigilance — Lots séparés ou constructeur à l'expérience limitée | K37: Trois lots séparés (génie civil, équipements, électricité) coordonnés par la SPV.
H38: Critique | I38: =Paramètres!$B$8 -> 20 | J38: Critique — Pas d'EPC signé ou constructeur fragile | K38: EPC non signé (voir verrou B2) ou constructeur en difficulté financière.
H39: Info. insuffisante | I39: =Paramètres!$B$9 -> 20 | J39: Info. insuffisante | K39: Projet d'EPC non communiqué.
A40: D3 — Construction et achèvement | B40: 20 % / 8 % / 0 % | C40: D3.2 | D40: Interfaces et gouvernance de chantier | E40: 0.25 | F40: Combien d'intervenants doivent se coordonner sur le chantier, et qui contrôle ? | G40: Organigramme du chantier, contrat de l'ingénieur des prêteurs (lender's technical advisor). | H40: Très favorable | I40: =Paramètres!$B$5 -> 100 | J40: Très favorable — Interface unique, ingénieur indépendant des prêteurs mandaté | K40: Un seul constructeur responsable de tout, ingénieur indépendant mandaté par les banques.
H41: Favorable | I41: =Paramètres!$B$6 -> 80 | J41: Favorable — Interfaces peu nombreuses et contractualisées | K41: Deux interfaces contractualisées (constructeur et raccordement).
...

Sheet Noyau N1-N6
A1: Noyau financier D7 — N1 à N3 calculés, N4 à N6 choisis
A2: D7 pèse 25 % (construction), 28 % (montée en charge) ou 30 % (exploitation) du score.
A4: Code | B4: Indicateur | C4: Poids dans D7 | D4: Comment la note est obtenue | E4: Exemple
A5: N1 | B5: DSCR minimum, scénario central | C5: 0.25 | D5: Calculé : le plus faible DSCR de toutes les échéances est comparé aux seuils applicables (onglet Routage et seuils). ≥ seuil Favorable : 100 ; entre Vigilance et Favorable : 80 ; entre Critique et Vigilance : 50 ; sous le seuil Critique, ou un CFADS négatif : 20. | E5: Centrale solaire R1 en construction : seuils 1,05 / 1,15 / 1,25. DSCR minimum 1,296 ≥ 1,25 : N1 = 100 (cas C1).
A6: N2 | B6: DSCR minimum, scénario défavorable | C6: 0.2 | D6: Calculé de la même façon, sur l'échéancier après le choc défavorable (baisse du CFADS ou CFADS stressé saisi). | E6: Même centrale, production P90 et charges +10 % : DSCR 1,117, entre 1,05 et 1,15 : N2 = 50.
A7: N3 | B7: LLCR, ou financement à terminaison en construction | C7: 0.15 | D7: En construction (P1) : ressources engagées ÷ besoin total. ≥ 110 % : 100 ; ≥ 100 % : 80 ; ≥ 95 % avec plan de remédiation : 50 ; sinon 20 et blocage B3. Hors P1 : note saisie à partir du LLCR. | E7: Ressources 747 MMAD pour un besoin de 707 : 105,7 %, donc N3 = 80 (cas C1).
A9: N4 à N6 : situations à choisir dans la liste
A10: Domaine | B10: Poids P1 / P2 / P3 | C10: Clé | D10: Indicateur | E10: Poids dans D7 | F10: Ce qu'on évalue | G10: Pièces à vérifier | H10: Niveau | I10: Note | J10: Dans l'outil (liste) | K10: Exemple : on choisit ce niveau quand…
A11: D7 — Finance et trésorerie (noyau) | B11: 25 % / 28 % / 30 % | C11: N4 | D11: Liquidité (DSRA, lignes, cascade) | E11: 0.15 | F11: La liquidité de réserve : la SPV peut-elle payer ses échéances pendant un incident temporaire ? | G11: Contrat de crédit (DSRA, réserves), cascade des comptes (waterfall), état des comptes. | H11: Très favorable | I11: =Paramètres!$B$5 -> 100 | J11: Très favorable — DSRA ≥ 6 mois dotée, réserve de maintenance, cascade signée | K11: DSRA de 6 mois dotée dès le début, réserve de maintenance, cascade signée.
H12: Favorable | I12: =Paramètres!$B$6 -> 80 | J12: Favorable — DSRA ≥ 6 mois, autres réserves partielles | K12: DSRA de 6 mois, réserve de maintenance pas encore dotée.
H13: Vigilance | I13: =Paramètres!$B$7 -> 50 | J13: Vigilance — DSRA de 3 à 6 mois ou dotation progressive | K13: DSRA de 4 mois, ou constituée progressivement sur les flux.
H14: Critique | I14: =Paramètres!$B$8 -> 20 | J14: Critique — DSRA < 3 mois ou absente, pas de cascade | K14: DSRA de 2 mois ou absente (cas IMMO, aussi plafond C7).
H15: Info. insuffisante | I15: =Paramètres!$B$9 -> 20 | J15: Info. insuffisante | K15: Contrat de crédit non finalisé.
A16: D7 — Finance et trésorerie (noyau) | B16: 25 % / 28 % / 30 % | C16: N5 | D16: Levier et fonds propres à risque | E16: 0.15 | F16: Le levier : quelle part du projet est financée par la dette, et les fonds propres sont-ils réellement à risque ? | G16: Plan de financement, calendrier d'apport des fonds propres. | H16: Très favorable | I16: =Paramètres!$B$5 -> 100 | J16: Très favorable — Quote-part de dette ≤ 65 %, fonds propres versés en premier | K16: Dette 60 % du coût, fonds propres versés avant le premier tirage.
H17: Favorable | I17: =Paramètres!$B$6 -> 80 | J17: Favorable — Quote-part de dette de 65 à 75 % | K17: Dette 70 % du coût.
H18: Vigilance | I18: =Paramètres!$B$7 -> 50 | J18: Vigilance — Quote-part de dette de 75 à 85 % ou fonds propres versés au prorata | K18: Dette 80 %, ou fonds propres versés en même temps que la dette (au prorata).
H19: Critique | I19: =Paramètres!$B$8 -> 20 | J19: Critique — Quote-part de dette > 85 % ou fonds propres non engagés | K19: Dette 88 % du coût (cas IMMO, aussi plafond C9).
H20: Info. insuffisante | I20: =Paramètres!$B$9 -> 20 | J20: Info. insuffisante | K20: Plan de financement non arrêté.
A21: D7 — Finance et trésorerie (noyau) | B21: 25 % / 28 % / 30 % | C21: N6 | D21: Exposition résiduelle taux / change / refinancement | E21: 0.1 | F21: Ce qui reste exposé aux taux, au change et au refinancement après couvertures. | G21: Contrats de couverture (swap), devise des recettes et de la dette, profil d'amortissement. | H21: Très favorable | I21: =Paramètres!$B$5 -> 100 | J21: Très favorable — Tout en MAD, taux fixe ou couvert, amortissement complet | K21: Tout en dirhams, taux fixé par swap, dette remboursée entièrement à l'échéance.
H22: Favorable | I22: =Paramètres!$B$6 -> 80 | J22: Favorable — Exposition résiduelle faible (< 10 % du service), couverte pour l'essentiel | K22: Part en euros couverte à 90 % : exposition nette 5 % du service annuel.
H23: Vigilance | I23: =Paramètres!$B$7 -> 50 | J23: Vigilance — Exposition de 10 à 25 % du service ou ballon refinancé avec stratégie | K23: Exposition nette 16 % du service, ou ballon refinancé avec une stratégie approuvée.
H24: Critique | I24: =Paramètres!$B$8 -> 20 | J24: Critique — Exposition > 25 % du service ou refinancement sans stratégie | K24: Exposition 30 % du service (cas IND, plafond C6), ou ballon sans stratégie.
H25: Info. insuffisante | I25: =Paramètres!$B$9 -> 20 | J25: Info. insuffisante | K25: Structure de couverture non arrêtée.

Sheet Variantes sectorielles
A1: Variantes sectorielles — D2.1, D4.1, D4.3, D5.2
A2: L'outil propose la description du secteur choisi au bloc 1. Dernière colonne : le niveau retenu dans les cas d'étude de l'outil (fictifs).
A4: Sous-critère | B4: Secteur | C4: Très favorable (100) | D4: Favorable (80) | E4: Vigilance (50) | F4: Critique (20) | G4: Dans les cas d'étude de l'outil
A5: D2.1 Technologie et performance | B5: ENR — Énergies renouvelables | C5: Équipements de premier rang, productible P90 établi par un expert | D5: Équipements reconnus, productible P90 établi sur des données courtes | E5: Équipement récent ou productible établi par le développeur seul | F5: Productible non établi de façon indépendante | G5: C1 (Centrale solaire photovoltaïque 80 MWc) : Très favorable C5 (Centrale PV d’autoproduction 12 MWc) : Très favorable ENR (Parc éolien terrestre 140 MW) : Très favorable
A6: D2.1 Technologie et performance | B6: EAU — Eau et dessalement | C6: Procédé avec ≥ 3 références comparables, consommation garantie | D6: Procédé éprouvé, références de taille inférieure | E6: Procédé extrapolé ou consommation énergétique non garantie | F6: Procédé sans référence de taille comparable | G6: C2 (Usine de dessalement 100 000 m³/jour) : Très favorable EAU (Usine de dessalement couplée à l'irrigat) : Favorable
A7: D2.1 Technologie et performance | B7: TEL — Télécom et data centers | C7: Conception Tier III certifiée, équipements standard du marché | D7: Conception Tier III, certification en cours | E7: Redondances partielles ou équipements spécifiques | F7: Conception non redondante ou technologie dépassée | G7: TEL (Centre de données Tier III, 24 MW inform) : Très favorable
A8: D2.1 Technologie et performance | B8: TRA — Transport | C8: Ouvrages courants, techniques de construction maîtrisées | D8: Ouvrages d'art standards, quelques sections complexes | E8: Ouvrages d'art majeurs ou terrain difficile | F8: Technique de construction non éprouvée localement | G8: TRA (Autoroute à péage de 95 km) : Très favorable
A9: D2.1 Technologie et performance | B9: POR — Ports et logistique | C9: Équipements de manutention standard, références multiples | D9: Équipements éprouvés, automatisation partielle | E9: Terminal fortement automatisé, références limitées | F9: Système de manutention prototype | G9: POR (Terminal à conteneurs de 1,2 million d'E) : Favorable
A10: D2.1 Technologie et performance | B10: SAN — Santé | C10: Bâtiment et plateau technique standard, normes hospitalières | D10: Plateau technique éprouvé, quelques équipements de pointe | E10: Équipements de pointe dépendant d'un fournisseur unique | F10: Conception non conforme aux normes hospitalières | G10: SAN (Centre hospitalier de 600 lits en parten) : Favorable
A11: D2.1 Technologie et performance | B11: ETH — Thermique et gaz | C11: Turbines de série, rendement garanti, références nombreuses | D11: Équipements éprouvés, rendement garanti partiellement | E11: Modèle récent ou conversion de combustible | F11: Technologie sans historique d'exploitation | G11: ETH (Centrale à cycle combiné au gaz de 450 M) : Favorable
A12: D2.1 Technologie et performance | B12: IMMO-REND — Immobilier de rendement | C12: Construction standard, certification énergétique obtenue | D12: Construction standard, certification en cours | E12: Bâtiment spécifique difficile à reconvertir | F12: Bâtiment obsolète ou non conforme | G12: IMMO (Ensemble de bureaux et commerces loués, ) : Très favorable
A13: D2.1 Technologie et performance | B13: IND — Industrie | C13: Procédé industriel éprouvé, garanties de performance du fournisseur | D13: Procédé éprouvé, garanties partielles | E13: Procédé adapté ou montée en cadence incertaine | F13: Procédé pilote ou non éprouvé à l'échelle | G13: IND (Usine de verre plat de 600 tonnes/jour) : Favorable
A14: D2.1 Technologie et performance | B14: AGR — Agro-industrie | C14: Itinéraire technique maîtrisé, rendements de référence documentés | D14: Itinéraire maîtrisé, rendements sur historique court | E14: Nouvelle culture ou nouvelle transformation sur ce site | F14: Rendements non documentés | G14: C4A (Unité agro-industrielle de trituration e) : Favorable C4B (Unité agro-industrielle — structure rest) : Favorable AGR (Unité de trituration d'olives et de cond) : Favorable
A15: D2.1 Technologie et performance | B15: TOU — Tourisme et hôtellerie | C15: Concept éprouvé, marque internationale, conception validée | D15: Concept éprouvé, adaptation au site en cours | E15: Concept nouveau sur ce marché | F15: Concept non validé | G15: C3 (Hôtel 4 étoiles, 220 clés) : Très favorable TOU (Complexe hôtelier balnéaire de 420 chamb) : Favorable
... A52: D5.2 Performance technique et disponibilité | B52: MIN — Mines et extraction | C52: Teneurs et récupération conformes au plan minier | D52: Écarts mineurs de teneur ou de récupération | E52: Teneur ou récupération inférieure au plan | F52: Écarts majeurs remettant en cause le plan minier | G52: MIN (Mine de cuivre à ciel ouvert et usine de) : Favorable

Sheet Routage et seuils
A1: Routage et seuils DSCR
A2: Seuil applicable = base du régime + écart sectoriel Δ + majoration de phase. Calculateur : changez les cellules bleues.
A4: Régime | B4: Libellé | C4: Critique < | D4: Vigilance < | E4: Favorable < | F4: Exemple | H4: Calculateur
A5: R1 | B5: Contrat ferme à quantité garantie (take-or-pay) | C5: 1.1 | D5: 1.2 | E5: 1.3 | F5: Centrale vendant toute sa production à un acheteur public (take-or-pay). | H5: Régime | I5: R4
A6: R2 | B6: Paiement à la disponibilité | C6: 1.12 | D6: 1.22 | E6: 1.32 | F6: Hôpital ou dessalement payé à la disponibilité. | H6: Secteur | I6: TOU
A7: R3 | B7: Contrat à risque de volume | C7: 1.2 | D7: 1.35 | E7: 1.5 | F7: Terminal portuaire, centre de données : volume en partie garanti. | H7: Phase | I7: P2
A8: R4 | B8: Exposition au marché | C8: 1.35 | D8: 1.55 | E8: 1.8 | F8: Autoroute à péage, hôtel, mine : recettes au prix du marché.
H9: Seuil Critique < | I9: =INDEX($C$5:$C$8,MATCH($I$5,$A$5:$A$8,0))+INDEX($C$12:$C$23,MATCH($I$6,$A$12:$A$23,0))+INDEX($C$27:$C$29,MATCH($I$7,$A$27:$A$29,0)) -> 1.6
H10: Seuil Vigilance < | I10: =INDEX($D$5:$D$8,MATCH($I$5,$A$5:$A$8,0))+INDEX($C$12:$C$23,MATCH($I$6,$A$12:$A$23,0))+INDEX($C$27:$C$29,MATCH($I$7,$A$27:$A$29,0)) -> 1.8
A11: Secteur | B11: Libellé | C11: Δ | H11: Seuil Favorable < | I11: =INDEX($E$5:$E$8,MATCH($I$5,$A$5:$A$8,0))+INDEX($C$12:$C$23,MATCH($I$6,$A$12:$A$23,0))+INDEX($C$27:$C$29,MATCH($I$7,$A$27:$A$29,0)) -> 2.05
A12: ENR | B12: Énergies renouvelables | C12: -0.05
A13: EAU | B13: Eau et dessalement | C13: 0 | H13: DSCR minimum du dossier | I13: 1.059
A14: TEL | B14: Télécom et data centers | C14: 0 | H14: Note N1 | I14: =IF(I13<I9,Paramètres!$B$8,IF(I13<I10,Paramètres!$B$7,IF(I13<I11,Paramètres!$B$6,Paramètres!$B$5))) -> 20
A15: TRA | B15: Transport | C15: 0.05 | H15: Plafond C2 (DSCR sous le seuil critique) | I15: =IF(I13<I9,"Actif : note ≤ 5","Non") -> Actif : note ≤ 5
A16: POR | B16: Ports et logistique | C16: 0.05 | H16: Exemple pré-rempli : hôtel du cas C3 (R4, tourisme, montée en charge) : seuil critique 1,35 + 0,20 + 0,05 = 1,60 ; son DSCR 1,059 donne N1 = 20 et active C2.
A17: SAN | B17: Santé | C17: 0.05
A18: ETH | B18: Thermique et gaz | C18: 0.05
A19: IMMO-REND | B19: Immobilier de rendement | C19: 0.05
A20: IND | B20: Industrie | C20: 0.1
A21: AGR | B21: Agro-industrie | C21: 0.15
A22: TOU | B22: Tourisme et hôtellerie | C22: 0.2
A23: MIN | B23: Mines et extraction | C23: 0.25
A26: Phase | B26: Libellé | C26: Majoration
A27: P1 | B27: Construction | C27: 0
A28: P2 | B28: Montée en charge | C28: 0.05
A29: P3 | B29: Exploitation | C29: 0
A32: Domaine | B32: Libellé | C32: P1 construction | D32: P2 montée en charge | E32: P3 exploitation
A33: D1 | B33: Sponsors et actionnariat | C33: 0.1 | D33: 0.08 | E33: 0.05
A34: D2 | B34: Projet, site, technologie | C34: 0.1 | D34: 0.07 | E34: 0.05
A35: D3 | B35: Construction et achèvement | C35: 0.2 | D35: 0.08 | E35: 0
A36: D4 | B36: Mécanisme des recettes | C36: 0.05 | D36: 0.12 | E36: 0.15
A37: D5 | B37: Exploitation et maintenance | C37: 0.05 | D37: 0.12 | E37: 0.15
A38: D6 | B38: Contreparties et consortium | C38: 0.1 | D38: 0.12 | E38: 0.15
A39: D7 | B39: Finance et trésorerie (noyau) | C39: 0.25 | D39: 0.28 | E39: 0.3
A40: D8 | B40: Juridique, sûretés, continuité | C40: 0.1 | D40: 0.08 | E40: 0.1
A41: D9 | B41: ESG et climat résiduel | C41: 0.05 | D41: 0.05 | E41: 0.05
B42: Total (doit faire 100 %) | C42: =SUM(C33:C41) -> 1 | D42: =SUM(D33:D41) -> 1 | E42: =SUM(E33:E41) -> 1

Sheet Plafonds
A1: Plafonds C1 à C15 — déclenchés par les données
A2: La note approuvée ne peut dépasser le plafond actif le plus bas. Le chargé d'affaires ne les choisit pas : il saisit les données, l'outil les évalue.
A4: Code | B4: Fait générateur | C4: Note maximale | D4: Exemple (cas d'étude fictifs)
A5: C1 | B5: DSCR minimum de base inférieur à 1,05x sur une échéance | C5: 3 | D5: Hôtel dont le CFADS de basse saison est négatif : DSCR −0,19 (cas TOU).
A6: C2 | B6: DSCR minimum de base sous le seuil critique du couple régime × secteur | C6: 5 | D6: Autoroute R4 : DSCR minimum 1,367 sous le seuil de 1,40 (cas TRA).
A7: C3 | B7: DSCR minimum sous scénario défavorable inférieur à 1,00x | C7: 4 | D7: Centre de données : départ d'un client de 4 MW, DSCR stressé 0,987 (cas TEL).
A8: C4 | B8: LLCR inférieur à 1,10x | C8: 4 | D8: Centrale à gaz : LLCR 1,08 (cas ETH).
A9: C5 | B9: Contrat de revenus expirant avant la dernière échéance de dette, sans solution documentée | C9: 5 | D9: Contrat d'enlèvement de 8 ans pour une dette de 12 ans, sans solution (cas IND).
A10: C6 | B10: Exposition nette en devises non couverte supérieure à 25 % du service de dette annuel | C10: 5 | D10: Dette en euros non couverte : 30 % du service annuel (cas IND).
A11: C7 | B11: DSRA absente ou inférieure à 3 mois de service de dette | C11: 6 | D11: Immeuble de bureaux avec 2 mois de DSRA (cas IMMO).
A12: C8 | B12: Dette à refinancer à maturité supérieure à 30 % du nominal, sans stratégie approuvée | C12: 5 | D12: Ballon de 35 % à refinancer, sans stratégie approuvée (cas ETH).
A13: C9 | B13: Quote-part de dette supérieure à 85 % du plan de financement | C13: 5 | D13: Dette 88 % du coût total (cas IMMO).
A14: C10 | B14: Acheteur portant plus de 85 % des recettes et de qualité interne inférieure à BBB− | C14: 6 | D14: Centrale d'autoproduction vendant 100 % à un industriel non noté (cas C5).
A15: C11 | B15: Risque climatique physique élevé au site sans plan d'adaptation financé | C15: 6 | D15: Hôtel littoral exposé à l'érosion, sans plan financé (cas TOU).
A16: C12 | B16: Capacité résiduelle du sponsor insuffisante pour l'appel d'equity restant | C16: 6 | D16: Sponsor minier sans capacité pour l'appel de fonds restant (cas MIN).
... A19: C15 | B19: Note issue d'une évaluation partielle (statut provisoire) | C19: 6 | D19: Deux sous-critères en « Info. insuffisante » (cas SAN).

Sheet Verrous
A1: Verrous — exclusions X et blocages B
A2: Exclusion X : aucune note n'est produite. Blocage B : la note est calculée mais reste provisoire ; le stade bloqué est indiqué.
A4: Code | B4: Fait générateur | C4: Effet | D4: Exemple
A5: X1 | B5: Activité interdite par la loi marocaine ou par la politique d'exclusion de la banque | C5: Aucune note | D5: Projet de jeux d'argent exclu par la politique de la banque.
A6: X2 | B6: Autorisation légalement indispensable juridiquement impossible à obtenir | C6: Aucune note | D6: Projet sur une zone où la loi interdit toute construction.
A7: X3 | B7: Contrepartie clé sous sanctions ou signalée au titre du dispositif LBC-FT | C7: Aucune note | D7: Acheteur unique de la production sous sanctions internationales (cas MIN).
A8: X4 | B8: Contrepartie clé en défaut avéré non régularisé | C8: Aucune note | D8: EPC confié à un constructeur en défaut de paiement avéré.
A9: B1 | B9: Contrat de revenus principal non signé (régimes R1 à R3) | C9: Note provisoire — bloque : Octroi | D9: Contrat d'achat d'électricité encore en négociation.
A10: B2 | B10: Contrat EPC non signé en phase P1 | C10: Note provisoire — bloque : Octroi | D10: Terminal portuaire en construction sans EPC signé (cas POR).
A11: B3 | B11: Besoin à terminaison supérieur aux ressources engagées (couverture < 95 % en P1) | C11: Note provisoire — bloque : Décaissement | D11: Mine en construction : ressources couvrant 92 % du besoin (cas MIN).
A12: B4 | B12: Droit d'occupation du site non établi, ou durée < dette + 24 mois | C12: Note provisoire — bloque : Octroi | D12: Hôtel dont le droit d'occupation du domaine n'est pas établi (cas TOU).
A13: B5 | B13: Avis juridique d'opposabilité des sûretés absent ou avec réserve substantielle | C13: Note provisoire — bloque : Décaissement | D13: Avis juridique avec réserve sur le nantissement des créances (cas IND).
A14: B6 | B14: Modèle de flux datés absent ou non rapproché des états financiers | C14: Note provisoire — bloque : Notation validée | D14: Pas de modèle de flux daté, ou non rapproché des comptes.
A15: B7 | B15: Complétude des critères critiques inférieure à 100 % | C15: Note provisoire — bloque : Notation validée | D15: Deux sous-critères en « Info. insuffisante » (cas SAN).
A16: B8 | B16: Acceptabilité environnementale non obtenue au stade requis | C16: Note provisoire — bloque : Octroi | D16: Étude d'impact environnemental non approuvée (cas MIN).

Sheet Conversion
A1: Conversion du score en note
A2: Calculateur : saisissez un score et un plafond éventuel (cellules bleues).
A4: Score à partir de | B4: Note | C4: Libellé | D4: Orientation | F4: Score global (sur 100) | G4: 73.7
A5: 0 | B5: 1 | C5: Très critique | D5: Refus ou restructuration complète | F5: Note calculée | G5: =INDEX($B$5:$B$14,MATCH(G4,$A$5:$A$14,1)) -> 7
A6: 32 | B6: 2 | C6: Critique | D6: Refus en l'état | F6: Plafond actif le plus bas (10 = aucun) | G6: 4
A7: 42 | B7: 3 | C7: Préoccupant | D7: Révision de fond | F7: Note approuvée | G7: =MIN(G5,G6) -> 4
A8: 50 | B8: 4 | C8: Fragile | D8: Restructuration à examiner | F8: Libellé | G8: =INDEX($C$5:$C$14,MATCH(G7,$B$5:$B$14,0)) -> Fragile
A9: 58 | B9: 5 | C9: Moyen | D9: Sous surveillance | F9: Exemple pré-rempli : hôtel C3, score 73,7 (note 7) plafonné à 4 par C3.
A10: 66 | B10: 6 | C10: Acceptable | D10: Conditions et mitigants
A11: 73 | B11: 7 | C11: Satisfaisant | D11: Conditions légères
A12: 80 | B12: 8 | C12: Solide | D12: Réserves mineures à documenter
A13: 86 | B13: 9 | C13: Très solide | D13: Conditions minimales
A14: 92 | B14: 10 | C14: Excellent | D14: Profil de référence

Sheet Exemple de calcul
A1: Exemple de calcul complet — cas C1, centrale solaire de 80 MWc (fictif)
A2: Phase P1 (construction). Les notes sont celles choisies dans l'outil ; tout le reste est calculé ici par formule.
A4: Domaine | B4: Clé | C4: Sous-critère | D4: Niveau choisi | E4: Note | F4: Poids | G4: Note × poids
A5: D1 | B5: D1.1 | C5: Capacité financière du sponsor | D5: Favorable | E5: =Paramètres!$B$6 -> 80 | F5: 0.4 | G5: =E5*F5 -> 32
A6: D1 | B6: D1.2 | C6: Obligation juridique de soutien | D6: Très favorable | E6: =Paramètres!$B$5 -> 100 | F6: 0.35 | G6: =E6*F6 -> 35
A7: D1 | B7: D1.3 | C7: Structure actionnariale et gouvernance | D7: Favorable | E7: =Paramètres!$B$6 -> 80 | F7: 0.25 | G7: =E7*F7 -> 20
C8: Score D1 | G8: =SUM(G5:G7) -> 87
A9: D2 | B9: D2.1 | C9: Technologie et performance | D9: Très favorable | E9: =Paramètres!$B$5 -> 100 | F9: 0.35 | G9: =E9*F9 -> 35
A10: D2 | B10: D2.2 | C10: Site, foncier physique et accès | D10: Favorable | E10: =Paramètres!$B$6 -> 80 | F10: 0.4 | G10: =E10*F10 -> 32
A11: D2 | B11: D2.3 | C11: Planning et complexité d'exécution | D11: Favorable | E11: =Paramètres!$B$6 -> 80 | F11: 0.25 | G11: =E11*F11 -> 20
C12: Score D2 | G12: =SUM(G9:G11) -> 87
A13: D3 | B13: D3.1 | C13: Contrat EPC et constructeur | D13: Très favorable | E13: =Paramètres!$B$5 -> 100 | F13: 0.4 | G13: =E13*F13 -> 40
A14: D3 | B14: D3.2 | C14: Interfaces et gouvernance de chantier | D14: Favorable | E14: =Paramètres!$B$6 -> 80 | F14: 0.25 | G14: =E14*F14 -> 20
A15: D3 | B15: D3.3 | C15: Assurances et garanties mobilisables | D15: Favorable | E15: =Paramètres!$B$6 -> 80 | F15: 0.35 | G15: =E15*F15 -> 28
C16: Score D3 | G16: =SUM(G13:G15) -> 88
A17: D4 | B17: D4.1 | C17: Structure contractuelle des recettes | D17: Très favorable | E17: =Paramètres!$B$5 -> 100 | F17: 0.45 | G17: =E17*F17 -> 45
A18: D4 | B18: D4.2 | C18: Mécanisme de prix et indexation | D18: Favorable | E18: =Paramètres!$B$6 -> 80 | F18: 0.3 | G18: =E18*F18 -> 24
A19: D4 | B19: D4.3 | C19: Marché et concurrence | D19: Très favorable | E19: =Paramètres!$B$5 -> 100 | F19: 0.25 | G19: =E19*F19 -> 25
C20: Score D4 | G20: =SUM(G17:G19) -> 94
A21: D5 | B21: D5.1 | C21: Opérateur et contrat O&M | D21: Favorable | E21: =Paramètres!$B$6 -> 80 | F21: 0.35 | G21: =E21*F21 -> 28
A22: D5 | B22: D5.2 | C22: Performance technique et disponibilité | D22: Favorable | E22: =Paramètres!$B$6 -> 80 | F22: 0.4 | G22: =E22*F22 -> 32
A23: D5 | B23: D5.3 | C23: Coûts, gros entretien et dépendances | D23: Favorable | E23: =Paramètres!$B$6 -> 80 | F23: 0.25 | G23: =E23*F23 -> 20
C24: Score D5 | G24: =SUM(G21:G23) -> 80
A25: D6 | B25: D6.1 | C25: Acheteur ou payeur principal | D25: Favorable | E25: =Paramètres!$B$6 -> 80 | F25: 0.5 | G25: =E25*F25 -> 40
A26: D6 | B26: D6.2 | C26: Fournisseurs critiques | D26: Vigilance | E26: =Paramètres!$B$7 -> 50 | F26: 0.2 | G26: =E26*F26 -> 10
A27: D6 | B27: D6.3 | C27: Prêteurs et consortium | D27: Très favorable | E27: =Paramètres!$B$5 -> 100 | F27: 0.3 | G27: =E27*F27 -> 30
C28: Score D6 | G28: =SUM(G25:G27) -> 80
A29: D8 | B29: D8.1 | C29: Documentation contractuelle et droits directs | D29: Favorable | E29: =Paramètres!$B$6 -> 80 | F29: 0.35 | G29: =E29*F29 -> 28
A30: D8 | B30: D8.2 | C30: Sûretés et opposabilité | D30: Favorable | E30: =Paramètres!$B$6 -> 80 | F30: 0.4 | G30: =E30*F30 -> 32
A31: D8 | B31: D8.3 | C31: Autorisations, cadre réglementaire, litiges | D31: Très favorable | E31: =Paramètres!$B$5 -> 100 | F31: 0.25 | G31: =E31*F31 -> 25
C32: Score D8 | G32: =SUM(G29:G31) -> 85
A33: D9 | B33: D9.1 | C33: Environnement et ressources | D33: Très favorable | E33: =Paramètres!$B$5 -> 100 | F33: 0.3 | G33: =E33*F33 -> 30
A34: D9 | B34: D9.2 | C34: Social et acceptabilité | D34: Favorable | E34: =Paramètres!$B$6 -> 80 | F34: 0.3 | G34: =E34*F34 -> 24
A35: D9 | B35: D9.3 | C35: Gouvernance ESG et exécution | D35: Favorable | E35: =Paramètres!$B$6 -> 80 | F35: 0.15 | G35: =E35*F35 -> 12
A36: D9 | B36: D9.4 | C36: Climat résiduel | D36: Favorable | E36: =Paramètres!$B$6 -> 80 | F36: 0.25 | G36: =E36*F36 -> 20
C37: Score D9 | G37: =SUM(G33:G36) -> 86
A39: Noyau D7
A40: Code | C40: Indicateur | D40: Comment | E40: Note | F40: Poids | G40: Note × poids
A41: N1 | C41: DSCR minimum, scénario central | D41: DSCR min 1,296 ≥ 1,25 | E41: =Paramètres!$B$5 -> 100 | F41: 0.25 | G41: =E41*F41 -> 25
A42: N2 | C42: DSCR minimum, scénario défavorable | D42: DSCR stressé 1,117 | E42: =Paramètres!$B$7 -> 50 | F42: 0.2 | G42: =E42*F42 -> 10
...

Sheet Glossaire
A1: Glossaire des termes techniques
A2: Avec un exemple chiffré fictif pour chaque terme.
A4: Terme | B4: Définition | C4: Exemple
A5: CFADS | B5: Cash Flow Available for Debt Service : trésorerie disponible pour payer la dette, après charges d'exploitation, impôts et investissements de maintien. | C5: Recettes 73 − charges 11 − impôts et maintien 8 = CFADS 54 MMAD.
A6: DSCR | B6: Debt Service Coverage Ratio : CFADS de la période ÷ service de la dette (intérêts + capital) de la période. | C6: CFADS semestriel 25,9 ÷ échéance 19,45 = DSCR 1,33.
A7: LLCR | B7: Loan Life Coverage Ratio : valeur actualisée des CFADS sur la durée du prêt ÷ dette restante. | C7: VA des CFADS 680 ÷ dette 500 = LLCR 1,36.
A8: DSRA | B8: Debt Service Reserve Account : compte de réserve bloqué, exprimé en mois de service de la dette. | C8: Échéance semestrielle de 19,45 : DSRA de 6 mois = 19,45 MMAD bloqués.
A9: Financement à terminaison | B9: En construction : les ressources engagées couvrent-elles tout le besoin jusqu'à la mise en service ? | C9: Ressources 747 ÷ besoin 707 = 105,7 % : couverture suffisante.
A10: Take-or-pay | B10: Contrat où l'acheteur paie une quantité garantie, qu'il la prenne ou non. | C10: L'office public paie 152 GWh par an même s'il n'en consomme que 140.
A11: Paiement à la disponibilité | B11: L'autorité paie si l'ouvrage est disponible, quel que soit l'usage. | C11: L'hôpital est payé s'il est ouvert et conforme, même avec peu de patients.
A12: EPC | B12: Engineering, Procurement, Construction : contrat clé-en-main confiant toute la construction à un seul constructeur. | C12: Le constructeur livre la centrale finie à prix et date garantis.
A13: O&M | B13: Operation and Maintenance : contrat d'exploitation et d'entretien. | C13: Un opérateur spécialisé exploite l'usine pendant 15 ans.
A14: SPV | B14: Special Purpose Vehicle : société créée pour porter un seul projet ; la banque prête à cette société. | C14: « Solaris Drâa SA » ne possède que la centrale.
A15: Sponsor | B15: Actionnaire qui développe le projet et apporte les fonds propres. | C15: Énergéticien international qui détient 60 % de la SPV.
... A24: Information insuffisante | B24: Pièce manquante : comptée 20 (comme Critique), note provisoire, commentaire exigé. | C24: Étude d'impact social non remise (cas SAN).

Sheet Paramètres
A1: Paramètres utilisés par cette grille
A2: Valeurs candidates du modèle (identiques à l'onglet Paramètres de l'outil). Modifiez une cellule bleue : toute la grille suit.
A4: Niveau | B4: Note | D4: « Info. insuffisante » est comptée comme Critique (20), rend la note provisoire (blocage B7, plafond C15) et exige un commentaire.
A5: Très favorable | B5: 100
A6: Favorable | B6: 80
A7: Vigilance | B7: 50
A8: Critique | B8: 20
A9: Info. insuffisante | B9: 20
