Workbook
Name IA_Champs: 'Champs IA'!$A$12:$D$472
Name L_Avis: 'Paramètres'!$C$82:$C$85
Name L_Decision: 'Paramètres'!$D$82:$D$85
Name L_Devise: 'Paramètres'!$B$82:$B$85
Name L_Nature: 'Paramètres'!$D$70:$D$77
Name L_NatureCredit: 'Paramètres'!$A$82:$A$87
Name L_Notes: 'Paramètres'!$B$70:$B$74
Name L_OuiNon: 'Paramètres'!$A$70:$A$71
Name L_Periodicite: 'Paramètres'!$C$70:$C$72
Name L_QualAch: 'Paramètres'!$E$70:$E$72
Name P_Ancre_C: 'Paramètres'!$C$63
Name P_Ancre_F: 'Paramètres'!$C$61
Name P_Ancre_TF: 'Paramètres'!$C$60
Name P_Ancre_V: 'Paramètres'!$C$62
Name P_C10: 'Paramètres'!$J$55
Name P_C13: 'Paramètres'!$J$56
Name P_C1: 'Paramètres'!$J$48
Name P_C3: 'Paramètres'!$J$49
Name P_C4: 'Paramètres'!$J$50
Name P_C6: 'Paramètres'!$J$51
Name P_C7: 'Paramètres'!$J$52
Name P_C8: 'Paramètres'!$J$53
Name P_C9: 'Paramètres'!$J$54
Name P_ConvLib: 'Paramètres'!$J$6:$J$15
Name P_ConvNote: 'Paramètres'!$I$6:$I$15
Name P_ConvOrient: 'Paramètres'!$K$6:$K$15
Name P_ConvSeuil: 'Paramètres'!$H$6:$H$15
Name P_COUV: 'Paramètres'!$J$57
Name P_Crit: 'Paramètres'!$C$6:$C$9
Name P_DomCodes: 'Paramètres'!$A$37:$A$45
Name P_DomLib: 'Paramètres'!$B$37:$B$45
Name P_Fav: 'Paramètres'!$E$6:$E$9
Name P_InfoInsuff: 'Paramètres'!$C$64
Name P_L_CAPEX: 'Paramètres'!$J$42
Name P_L_EXPO: 'Paramètres'!$J$43
Name P_L_NBCP: 'Paramètres'!$J$44
Name P_N3_F: 'Paramètres'!$J$46
Name P_N3_TF: 'Paramètres'!$J$45
Name P_N3_V: 'Paramètres'!$J$47
Name P_PhaseCodes: 'Paramètres'!$A$30:$A$32
Name P_PhaseLib: 'Paramètres'!$B$30:$B$32
Name P_PhaseMaj: 'Paramètres'!$C$30:$C$32
Name P_PlafCode: 'Paramètres'!$H$20:$H$34
Name P_PlafFait: 'Paramètres'!$I$20:$I$34
Name P_PlafNiv: 'Paramètres'!$J$20:$J$34
Name P_PoidsDom: 'Paramètres'!$C$37:$E$45
Name P_PoidsHdr: 'Paramètres'!$C$36:$E$36
Name P_PoidsN: 'Paramètres'!$C$50:$C$55
Name P_Regimes: 'Paramètres'!$A$6:$A$9
Name P_RegLib: 'Paramètres'!$B$6:$B$9
Name P_S_CAPEX: 'Paramètres'!$J$39
Name P_S_DUREE: 'Paramètres'!$J$41
Name P_S_EXPO: 'Paramètres'!$J$40
Name P_SCCle: 'Paramètres'!$H$62:$H$86
Name P_SCPoids: 'Paramètres'!$J$62:$J$86
Name P_SecCodes: 'Paramètres'!$A$14:$A$25
Name P_SecDelta: 'Paramètres'!$C$14:$C$25
Name P_SecLib: 'Paramètres'!$B$14:$B$25
Name P_Vig: 'Paramètres'!$D$6:$D$9
Name R_Cles: 'Référentiel des niveaux'!$J$8:$J$83

Sheet Accueil
B2: Outil de scoring Project Finance — modèle V8
B3: Version 3 · dix-huit dossiers préchargés · situations descriptives · commentaires et conditions · comparaison · concordance · import des propositions de l'IA.
B5: SCORER UN PROJET EN 5 ÉTAPES
B6: 1. Cliquez « Nouveau dossier » (à droite) : dossier vide, ou copie d'un dossier existant avec « Dupliquer ». Avec un fichier de propositions de l'IA, cliquez « Nouveau dossier depuis l'IA ».
B7: 2. Saisissez d'abord les codes (client T24, radical à 7 chiffres, code projet PF-AAAA-NNNN), puis remplissez les cellules ORANGE : ce sont les saisies obligatoires encore vides. Sélectionnez une cellule pour lire son aide.
B8: 3. Grille et indicateurs N4 à N6 : choisissez dans la liste la situation qui décrit le dossier ; la note s'affiche à côté. Une situation Critique ou « Info. insuffisante » exige un commentaire.
B9: 4. Lisez le tableau de bord : note approuvée, plafonds et verrous actifs, statut. Rédigez le bloc 13 « Commentaires et conditions » : synthèse obligatoire, justification des écarts si un plafond ou un verrou est actif.
B10: 5. Cliquez « Contrôler la saisie », puis « Fiche comité » pour imprimer la page de présentation ou l'exporter en PDF.
B12: LÉGENDE
B13: Saisie | C13: Saisie obligatoire manquante | D13: Calcul | E13: Note ≥ 8 | F13: Note 6 ou 7 | G13: Note ≤ 5
B14: Les cellules de calcul sont protégées (sans mot de passe) pour éviter d'écraser une formule par erreur. Pour modifier la structure : onglet Révision › Ôter la protection de la feuille.
B16: CATALOGUE DES 18 CAS D'ÉTUDE — dossiers fictifs ; cliquez sur un onglet pour l'ouvrir
B17: Onglet | C17: Projet | D17: Code projet | E17: Secteur | F17: Régime · phase | G17: Note approuvée | H17: Situations illustrées | I17: Ce que ce cas enseigne
B18: C1 | C18: Centrale solaire photovoltaïque 80 MWc | D18: PF-2026-0001 | E18: ENR | F18: R1 · P1 | G18: =IFERROR(INDIRECT("'C1'!B276"),"—") -> 0 | H18: Référence P1, contrat ferme R1 ; marge de financement à terminaison étroite (N3 = 80). | I18: Cas de référence. Deux points méritent attention malgré la note élevée : le test de financement à terminaison ne donne que 5,7 % de marge, ce qui vaut 8 et non 10 sur N3 ; et le DSCR sous stress P90 tombe à 1,12, soit Vigilance. Un dossier solide n'obtient pas 10 partout.
B19: C2 | C19: Usine de dessalement 100 000 m³/jour | D19: PF-2026-0002 | E19: EAU | F19: R2 · P2 | G19: =IFERROR(INDIRECT("'C2'!B276"),"—") -> 0 | H19: Paiement à la disponibilité R2 en montée en charge P2 ; risque énergie partiellement retenu. | I19: Un paiement à la disponibilité n'est pas un take-or-pay. L'acheteur porte le risque de demande ; le projet porte le risque de performance et, ici, une part du risque énergie. La phase de montée en charge relève le seuil de 0,05, et le stress énergie fait tomber N2 à 20, ce qui suffit à ramener le noyau à 57,5.
B20: C3 | C20: Hôtel 4 étoiles, 220 clés | D20: PF-2026-0003 | E20: TOU | F20: R4 · P2 | G20: =IFERROR(INDIRECT("'C3'!B276"),"—") -> 0 | H20: Anti-compensation : score 73,7 ramené à 4 par C2 et C3 (creux saisonnier). | I20: C'est la démonstration centrale du modèle. Le dossier est excellent presque partout : D1 et D8 à 100, D3 à 95, D2 à 95. Le score calculé atteint 73,7, soit la note 7. Mais le DSCR minimum tombe à 1,06 sur le creux estival, très en dessous du seuil critique de 1,60 applicable à un hôtel exposé au marché, et le DSCR sous stress passe sous 1,00. Les plafonds C2 et C3 ramènent la note approuvée à 4. Aucune qualité de sponsor ne compense une trésorerie qui ne couvre pas une échéance.
B21: C4A | C21: Unité agro-industrielle de trituration et conditionnement | D21: PF-2026-0004 | E21: AGR | F21: R3 · P3 | G21: =IFERROR(INDIRECT("'C4A'!B276"),"—") -> 0 | H21: Piège du ratio annuel : 1,53 en annuel, 0,59 par échéance ; change non couvert. | I21: Le piège du ratio annuel. Le DSCR annuel ressort à 1,53, ce qui aurait été lu comme Favorable sur l'ancienne ligne sectorielle agro-industrie. Le DSCR minimum par échéance est de 0,59 sur le semestre d'intercampagne : l'échéance n'est pas payable sans trésorerie externe. Le plafond C1 s'applique, le stress hydrique fait passer le DSCR stressé sous 1,00 (C3) et l'exposition de change non couverte déclenche C6.
B22: C4B | C22: Unité agro-industrielle — structure restructurée | D22: PF-2026-0004 | E22: AGR | F22: R3 · P3 | G22: =IFERROR(INDIRECT("'C4B'!B276"),"—") -> 0 | H22: Même projet que C4A restructuré : la note passe de 3 à 6 sans changement de marché. | I22: Trois corrections de montage, aucun changement de marché ni de grille qualitative, et la note passe de 3 à 6. Le modèle n'a pas seulement sanctionné : il a désigné précisément quoi corriger — le profil d'amortissement, le niveau de dette et la couverture de change.
B23: C5 | C23: Centrale PV d’autoproduction 12 MWc | D23: PF-2026-0005 | E23: ENR | F23: R1 · P1 | G23: =IFERROR(INDIRECT("'C5'!B276"),"—") -> 0 | H23: Régime simplifié S : grille allégée, plafonds intacts (C10, acheteur unique non noté). | I23: Le régime simplifié en action : 25 notes de sous-critère au lieu de 75, aucune revue externe imposée. Le noyau financier reste complet et ressort à 97, ce qui est excellent. Mais la concentration sur un acheteur unique non noté déclenche le plafond C10, et la note approuvée tombe de 8 à 6. Alléger la grille de jugement n'allège jamais les plafonds.
B24: ENR | C24: Parc éolien terrestre 140 MW | D24: PF-2026-0006 | E24: ENR | F24: R1 · P1 | G24: =IFERROR(INDIRECT("'ENR'!B276"),"—") -> 0 | H24: Dossier de référence : régime M, aucun plafond, note 10. | I24: Le dossier de référence : régime M (aucune condition d'escalade), toutes les mesures du noyau favorables, aucun plafond. Il montre ce qu'il faut réunir pour atteindre la note 10.
B25: EAU | C25: Usine de dessalement couplée à l'irrigation, 120 000 m³/jour | D25: PF-2026-0007 | E25: EAU | F25: R2 · P2 | G25: =IFERROR(INDIRECT("'EAU'!B276"),"—") -> 0 | H25: Montée en charge P2 ; climat élevé neutralisé par un plan financé ; régime L. | I25: Montre la majoration de phase P2 (+ 0,05 sur les seuils), le noyau hors construction (N3 fondé sur le LLCR), un risque climatique élevé neutralisé par un plan d'adaptation financé, et l'escalade en régime L par la durée du contrat et la part en devises.
B26: TEL | C26: Centre de données Tier III, 24 MW informatiques | D26: PF-2026-0008 | E26: TEL | F26: R3 · P2 | G26: =IFERROR(INDIRECT("'TEL'!B276"),"—") -> 0 | H26: Plafond C3 : DSCR défavorable sous 1,00 ; escalade M → L par le plafond. | I26: Le scénario défavorable fait tomber le DSCR sous 1,00 : plafond C3 (note 4 au plus) malgré un score de 6. Le plafond fait aussi passer le régime calculé M en régime L.
B27: TRA | C27: Autoroute à péage de 95 km | D27: PF-2026-0009 | E27: TRA | F27: R4 · P3 | G27: =IFERROR(INDIRECT("'TRA'!B276"),"—") -> 0 | H27: Régime R4 : seuils les plus exigeants ; C2 actif à 1,37 ; C5 sans objet. | I27: Régime R4 : les seuils DSCR sont les plus exigeants (1,40 critique avec Δ transport). Un DSCR minimum de 1,37 déclenche C2. Le plafond C5 est sans objet en R4, faute de contrat de recettes. Le régime R4 impose le régime L.
B28: POR | C28: Terminal à conteneurs de 1,2 million d'EVP | D28: PF-2026-0010 | E28: POR | F28: R3 · P1 | G28: =IFERROR(INDIRECT("'POR'!B276"),"—") -> 0 | H28: Construction sans EPC signé (B2) ; C10 et C14 ; couverture 97 % avec plan de remédiation. | I28: Construction avec un financement à terminaison couvert à 97 % seulement : N3 Vigilance grâce au plan de remédiation approuvé (sans plan, Critique). EPC non signé : blocage B2, note provisoire. Concentration sur un armateur non noté (C10) et exposition du groupe sur le transport maritime (C14).
B29: SAN | C29: Centre hospitalier de 600 lits en partenariat public-privé | D29: PF-2026-0011 | E29: SAN | F29: R2 · P1 | G29: =IFERROR(INDIRECT("'SAN'!B276"),"—") -> 0 | H29: Informations insuffisantes (B7, C15) ; opérateur non remplaçable (C13). | I29: Deux sous-critères en « Info. insuffisante » : ils comptent pour 20, la complétude tombe sous 100 % (blocage B7) et le plafond C15 s'applique. Le contrat de maintenance biomédicale expire 7 ans avant la dette avec un prestataire non remplaçable (C13).
B30: ETH | C30: Centrale à cycle combiné au gaz de 450 MW | D30: PF-2026-0012 | E30: ETH | F30: R1 · P3 | G30: =IFERROR(INDIRECT("'ETH'!B276"),"—") -> 0 | H30: LLCR sous 1,10 (C4) et ballon de 35 % sans stratégie (C8). | I30: Un LLCR de 1,08 déclenche C4 (note 4 au plus) ; le ballon de 35 % sans stratégie de refinancement approuvée déclenche C8 (5). Le plafond le plus contraignant s'applique : 4.
B31: IMMO | C31: Ensemble de bureaux et commerces loués, 48 000 m² | D31: PF-2026-0013 | E31: IMMO-REND | F31: R3 · P3 | G31: =IFERROR(INDIRECT("'IMMO'!B276"),"—") -> 0 | H31: Levier 88 % (C9) et DSRA de 2 mois (C7) ; N4 et N5 Critiques. | I31: Deux plafonds se cumulent : DSRA de 2 mois (C7, note 6 au plus) et quote-part de dette de 88 % (C9, note 5 au plus). La note approuvée retient le plus contraignant, 5. Le plafond fait passer le régime M en L.
B32: IND | C32: Usine de verre plat de 600 tonnes/jour | D32: PF-2026-0014 | E32: IND | F32: R3 · P2 | G32: =IFERROR(INDIRECT("'IND'!B276"),"—") -> 0 | H32: Avis juridique avec réserve (B5) ; contrat plus court que la dette (C5) ; change (C6). | I32: Différé : les deux premières périodes (service nul) sont signalées et exclues du DSCR minimum. Exposition en euros non couverte (C6) et contrat d'enlèvement plus court que la dette sans solution (C5). L'avis juridique sur les sûretés n'est pas reçu : blocage B5 au stade du décaissement.
B33: AGR | C33: Unité de trituration d'olives et de conditionnement d'huile | D33: PF-2026-0015 | E33: AGR | F33: R1 · P1 | G33: =IFERROR(INDIRECT("'AGR'!B276"),"—") -> 0 | H33: Régime S en construction : petit projet, contrat d'achat ferme, aucun plafond. | I33: Toutes les conditions du régime simplifié S sont réunies : dossier allégé. L'écart sectoriel Δ de + 0,15 rend les seuils plus exigeants qu'en énergie : un DSCR minimum de 1,37 n'est que Favorable.
B34: TOU | C34: Complexe hôtelier balnéaire de 420 chambres | D34: PF-2026-0016 | E34: TOU | F34: R4 · P2 | G34: =IFERROR(INDIRECT("'TOU'!B276"),"—") -> 0 | H34: CFADS négatif en basse saison (C1) ; droit d'occupation non établi (B4) ; climat sans plan (C11). | I34: Le cas le plus dégradé : seuils les plus élevés (R4, Δ tourisme + 0,20, majoration P2), CFADS négatif (N1 Critique d'office), DSCR minimum sous 1,05 (C1, note 3 au plus), risque d'érosion côtière sans plan (C11), et titre d'occupation insuffisant (B4).
B35: MIN | C35: Mine de cuivre à ciel ouvert et usine de concentration | D35: PF-2026-0017 | E35: MIN | F35: R4 · P1 | G35: =IFERROR(INDIRECT("'MIN'!B276"),"—") -> 0 | H35: Exclusion X3 (contrepartie sous sanctions) : aucune note ; B3 et B8 en plus. | I35: Une exclusion X (contrepartie clé sous sanctions) : aucune note n'est produite, quel que soit le score. Le calcul est présenté pour l'apprentissage : il montre aussi un financement à terminaison couvert à 92 % (N3 Critique et blocage B3 détecté automatiquement), un sponsor sans capacité résiduelle (C12) et l'acceptabilité environnementale non obtenue (B8).
B37: VOS DOSSIERS — tous les onglets de dossier, lus dans la synthèse
B38: Onglet | C38: Intitulé | D38: Code projet | E38: Phase | F38: Note approuvée | G38: Manquantes | H38: Statut
B39: =IF('Synthèse'!$B$4="","",HYPERLINK("#'"&'Synthèse'!$B$4&"'!A1",'Synthèse'!$B$4)) -> 0 | C39: =IF('Synthèse'!$B$4="","",'Synthèse'!$B$5) -> 0 | D39: =IF('Synthèse'!$B$4="","",'Synthèse'!$B$8) -> 0 | E39: =IF('Synthèse'!$B$4="","",'Synthèse'!$B$11) -> 0 | F39: =IF('Synthèse'!$B$4="","",'Synthèse'!$B$24) -> 0 | G39: =IF('Synthèse'!$B$4="","",'Synthèse'!$B$27) -> 0 | H39: =IF('Synthèse'!$B$4="","",'Synthèse'!$B$25) -> 0
B40: =IF('Synthèse'!$C$4="","",HYPERLINK("#'"&'Synthèse'!$C$4&"'!A1",'Synthèse'!$C$4)) -> 0 | C40: =IF('Synthèse'!$C$4="","",'Synthèse'!$C$5) -> 0 | D40: =IF('Synthèse'!$C$4="","",'Synthèse'!$C$8) -> 0 | E40: =IF('Synthèse'!$C$4="","",'Synthèse'!$C$11) -> 0 | F40: =IF('Synthèse'!$C$4="","",'Synthèse'!$C$24) -> 0 | G40: =IF('Synthèse'!$C$4="","",'Synthèse'!$C$27) -> 0 | H40: =IF('Synthèse'!$C$4="","",'Synthèse'!$C$25) -> 0
B41: =IF('Synthèse'!$D$4="","",HYPERLINK("#'"&'Synthèse'!$D$4&"'!A1",'Synthèse'!$D$4)) -> 0 | C41: =IF('Synthèse'!$D$4="","",'Synthèse'!$D$5) -> 0 | D41: =IF('Synthèse'!$D$4="","",'Synthèse'!$D$8) -> 0 | E41: =IF('Synthèse'!$D$4="","",'Synthèse'!$D$11) -> 0 | F41: =IF('Synthèse'!$D$4="","",'Synthèse'!$D$24) -> 0 | G41: =IF('Synthèse'!$D$4="","",'Synthèse'!$D$27) -> 0 | H41: =IF('Synthèse'!$D$4="","",'Synthèse'!$D$25) -> 0
B42: =IF('Synthèse'!$E$4="","",HYPERLINK("#'"&'Synthèse'!$E$4&"'!A1",'Synthèse'!$E$4)) -> 0 | C42: =IF('Synthèse'!$E$4="","",'Synthèse'!$E$5) -> 0 | D42: =IF('Synthèse'!$E$4="","",'Synthèse'!$E$8) -> 0 | E42: =IF('Synthèse'!$E$4="","",'Synthèse'!$E$11) -> 0 | F42: =IF('Synthèse'!$E$4="","",'Synthèse'!$E$24) -> 0 | G42: =IF('Synthèse'!$E$4="","",'Synthèse'!$E$27) -> 0 | H42: =IF('Synthèse'!$E$4="","",'Synthèse'!$E$25) -> 0
B43: =IF('Synthèse'!$F$4="","",HYPERLINK("#'"&'Synthèse'!$F$4&"'!A1",'Synthèse'!$F$4)) -> 0 | C43: =IF('Synthèse'!$F$4="","",'Synthèse'!$F$5) -> 0 | D43: =IF('Synthèse'!$F$4="","",'Synthèse'!$F$8) -> 0 | E43: =IF('Synthèse'!$F$4="","",'Synthèse'!$F$11) -> 0 | F43: =IF('Synthèse'!$F$4="","",'Synthèse'!$F$24) -> 0 | G43: =IF('Synthèse'!$F$4="","",'Synthèse'!$F$27) -> 0 | H43: =IF('Synthèse'!$F$4="","",'Synthèse'!$F$25) -> 0
B44: =IF('Synthèse'!$G$4="","",HYPERLINK("#'"&'Synthèse'!$G$4&"'!A1",'Synthèse'!$G$4)) -> 0 | C44: =IF('Synthèse'!$G$4="","",'Synthèse'!$G$5) -> 0 | D44: =IF('Synthèse'!$G$4="","",'Synthèse'!$G$8) -> 0 | E44: =IF('Synthèse'!$G$4="","",'Synthèse'!$G$11) -> 0 | F44: =IF('Synthèse'!$G$4="","",'Synthèse'!$G$24) -> 0 | G44: =IF('Synthèse'!$G$4="","",'Synthèse'!$G$27) -> 0 | H44: =IF('Synthèse'!$G$4="","",'Synthèse'!$G$25) -> 0
B45: =IF('Synthèse'!$H$4="","",HYPERLINK("#'"&'Synthèse'!$H$4&"'!A1",'Synthèse'!$H$4)) -> 0 | C45: =IF('Synthèse'!$H$4="","",'Synthèse'!$H$5) -> 0 | D45: =IF('Synthèse'!$H$4="","",'Synthèse'!$H$8) -> 0 | E45: =IF('Synthèse'!$H$4="","",'Synthèse'!$H$11) -> 0 | F45: =IF('Synthèse'!$H$4="","",'Synthèse'!$H$24) -> 0 | G45: =IF('Synthèse'!$H$4="","",'Synthèse'!$H$27) -> 0 | H45: =IF('Synthèse'!$H$4="","",'Synthèse'!$H$25) -> 0
...

Sheet Synthèse
A1: Synthèse des dossiers
A2: Une colonne par onglet de dossier, lue en direct : c'est le tableau comparatif de tous les cas. Les dossiers créés par « Nouveau dossier » sont ajoutés automatiquement ; sans macros, tapez le nom de l'onglet en ligne 4.
A4: Onglet | B4: C1 | C4: C2 | D4: C3 | E4: C4A | F4: C4B | G4: C5 | H4: ENR | I4: EAU | J4: TEL | K4: TRA | L4: POR | M4: SAN | N4: ETH | O4: IMMO | P4: IND | Q4: AGR | R4: TOU | S4: MIN
A5: Intitulé du dossier | B5: =IF(B$4="","",IFERROR(INDIRECT("'"&B$4&"'!"&$AQ5),"")) -> 0 | C5: =IF(C$4="","",IFERROR(INDIRECT("'"&C$4&"'!"&$AQ5),"")) -> 0 | D5: =IF(D$4="","",IFERROR(INDIRECT("'"&D$4&"'!"&$AQ5),"")) -> 0 | E5: =IF(E$4="","",IFERROR(INDIRECT("'"&E$4&"'!"&$AQ5),"")) -> 0 | F5: =IF(F$4="","",IFERROR(INDIRECT("'"&F$4&"'!"&$AQ5),"")) -> 0 | G5: =IF(G$4="","",IFERROR(INDIRECT("'"&G$4&"'!"&$AQ5),"")) -> 0 | H5: =IF(H$4="","",IFERROR(INDIRECT("'"&H$4&"'!"&$AQ5),"")) -> 0 | I5: =IF(I$4="","",IFERROR(INDIRECT("'"&I$4&"'!"&$AQ5),"")) -> 0 | ... AO5: =IF(AO$4="","",IFERROR(INDIRECT("'"&AO$4&"'!"&$AQ5),"")) -> 0 | AQ5: A1
A6: Code client T24 | B6: =IF(B$4="","",IFERROR(INDIRECT("'"&B$4&"'!"&$AQ6),"")) -> 0 | C6: =IF(C$4="","",IFERROR(INDIRECT("'"&C$4&"'!"&$AQ6),"")) -> 0 | D6: =IF(D$4="","",IFERROR(INDIRECT("'"&D$4&"'!"&$AQ6),"")) -> 0 | E6: =IF(E$4="","",IFERROR(INDIRECT("'"&E$4&"'!"&$AQ6),"")) -> 0 | F6: =IF(F$4="","",IFERROR(INDIRECT("'"&F$4&"'!"&$AQ6),"")) -> 0 | G6: =IF(G$4="","",IFERROR(INDIRECT("'"&G$4&"'!"&$AQ6),"")) -> 0 | H6: =IF(H$4="","",IFERROR(INDIRECT("'"&H$4&"'!"&$AQ6),"")) -> 0 | I6: =IF(I$4="","",IFERROR(INDIRECT("'"&I$4&"'!"&$AQ6),"")) -> 0 | ... AO6: =IF(AO$4="","",IFERROR(INDIRECT("'"&AO$4&"'!"&$AQ6),"")) -> 0 | AQ6: B15
A7: Radical | B7: =IF(B$4="","",IFERROR(INDIRECT("'"&B$4&"'!"&$AQ7),"")) -> 0 | C7: =IF(C$4="","",IFERROR(INDIRECT("'"&C$4&"'!"&$AQ7),"")) -> 0 | D7: =IF(D$4="","",IFERROR(INDIRECT("'"&D$4&"'!"&$AQ7),"")) -> 0 | E7: =IF(E$4="","",IFERROR(INDIRECT("'"&E$4&"'!"&$AQ7),"")) -> 0 | F7: =IF(F$4="","",IFERROR(INDIRECT("'"&F$4&"'!"&$AQ7),"")) -> 0 | G7: =IF(G$4="","",IFERROR(INDIRECT("'"&G$4&"'!"&$AQ7),"")) -> 0 | H7: =IF(H$4="","",IFERROR(INDIRECT("'"&H$4&"'!"&$AQ7),"")) -> 0 | I7: =IF(I$4="","",IFERROR(INDIRECT("'"&I$4&"'!"&$AQ7),"")) -> 0 | ... AO7: =IF(AO$4="","",IFERROR(INDIRECT("'"&AO$4&"'!"&$AQ7),"")) -> 0 | AQ7: B16
A8: Code projet | B8: =IF(B$4="","",IFERROR(INDIRECT("'"&B$4&"'!"&$AQ8),"")) -> 0 | C8: =IF(C$4="","",IFERROR(INDIRECT("'"&C$4&"'!"&$AQ8),"")) -> 0 | D8: =IF(D$4="","",IFERROR(INDIRECT("'"&D$4&"'!"&$AQ8),"")) -> 0 | E8: =IF(E$4="","",IFERROR(INDIRECT("'"&E$4&"'!"&$AQ8),"")) -> 0 | F8: =IF(F$4="","",IFERROR(INDIRECT("'"&F$4&"'!"&$AQ8),"")) -> 0 | G8: =IF(G$4="","",IFERROR(INDIRECT("'"&G$4&"'!"&$AQ8),"")) -> 0 | H8: =IF(H$4="","",IFERROR(INDIRECT("'"&H$4&"'!"&$AQ8),"")) -> 0 | I8: =IF(I$4="","",IFERROR(INDIRECT("'"&I$4&"'!"&$AQ8),"")) -> 0 | ... AO8: =IF(AO$4="","",IFERROR(INDIRECT("'"&AO$4&"'!"&$AQ8),"")) -> 0 | AQ8: B17
A9: Régime de revenus | B9: =IF(B$4="","",IFERROR(INDIRECT("'"&B$4&"'!"&$AQ9),"")) -> 0 | C9: =IF(C$4="","",IFERROR(INDIRECT("'"&C$4&"'!"&$AQ9),"")) -> 0 | D9: =IF(D$4="","",IFERROR(INDIRECT("'"&D$4&"'!"&$AQ9),"")) -> 0 | E9: =IF(E$4="","",IFERROR(INDIRECT("'"&E$4&"'!"&$AQ9),"")) -> 0 | F9: =IF(F$4="","",IFERROR(INDIRECT("'"&F$4&"'!"&$AQ9),"")) -> 0 | G9: =IF(G$4="","",IFERROR(INDIRECT("'"&G$4&"'!"&$AQ9),"")) -> 0 | H9: =IF(H$4="","",IFERROR(INDIRECT("'"&H$4&"'!"&$AQ9),"")) -> 0 | I9: =IF(I$4="","",IFERROR(INDIRECT("'"&I$4&"'!"&$AQ9),"")) -> 0 | ... AO9: =IF(AO$4="","",IFERROR(INDIRECT("'"&AO$4&"'!"&$AQ9),"")) -> 0 | AQ9: B18
A10: Secteur | B10: =IF(B$4="","",IFERROR(INDIRECT("'"&B$4&"'!"&$AQ10),"")) -> 0 | C10: =IF(C$4="","",IFERROR(INDIRECT("'"&C$4&"'!"&$AQ10),"")) -> 0 | D10: =IF(D$4="","",IFERROR(INDIRECT("'"&D$4&"'!"&$AQ10),"")) -> 0 | E10: =IF(E$4="","",IFERROR(INDIRECT("'"&E$4&"'!"&$AQ10),"")) -> 0 | F10: =IF(F$4="","",IFERROR(INDIRECT("'"&F$4&"'!"&$AQ10),"")) -> 0 | G10: =IF(G$4="","",IFERROR(INDIRECT("'"&G$4&"'!"&$AQ10),"")) -> 0 | H10: =IF(H$4="","",IFERROR(INDIRECT("'"&H$4&"'!"&$AQ10),"")) -> 0 | I10: =IF(I$4="","",IFERROR(INDIRECT("'"&I$4&"'!"&$AQ10),"")) -> 0 | ... AO10: =IF(AO$4="","",IFERROR(INDIRECT("'"&AO$4&"'!"&$AQ10),"")) -> 0 | AQ10: B19
A11: Phase | B11: =IF(B$4="","",IFERROR(INDIRECT("'"&B$4&"'!"&$AQ11),"")) -> 0 | C11: =IF(C$4="","",IFERROR(INDIRECT("'"&C$4&"'!"&$AQ11),"")) -> 0 | D11: =IF(D$4="","",IFERROR(INDIRECT("'"&D$4&"'!"&$AQ11),"")) -> 0 | E11: =IF(E$4="","",IFERROR(INDIRECT("'"&E$4&"'!"&$AQ11),"")) -> 0 | F11: =IF(F$4="","",IFERROR(INDIRECT("'"&F$4&"'!"&$AQ11),"")) -> 0 | G11: =IF(G$4="","",IFERROR(INDIRECT("'"&G$4&"'!"&$AQ11),"")) -> 0 | H11: =IF(H$4="","",IFERROR(INDIRECT("'"&H$4&"'!"&$AQ11),"")) -> 0 | I11: =IF(I$4="","",IFERROR(INDIRECT("'"&I$4&"'!"&$AQ11),"")) -> 0 | ... AO11: =IF(AO$4="","",IFERROR(INDIRECT("'"&AO$4&"'!"&$AQ11),"")) -> 0 | AQ11: B20
A12: Régime de proportionnalité retenu | B12: =IF(B$4="","",IFERROR(INDIRECT("'"&B$4&"'!"&$AQ12),"")) -> 0 | C12: =IF(C$4="","",IFERROR(INDIRECT("'"&C$4&"'!"&$AQ12),"")) -> 0 | D12: =IF(D$4="","",IFERROR(INDIRECT("'"&D$4&"'!"&$AQ12),"")) -> 0 | E12: =IF(E$4="","",IFERROR(INDIRECT("'"&E$4&"'!"&$AQ12),"")) -> 0 | F12: =IF(F$4="","",IFERROR(INDIRECT("'"&F$4&"'!"&$AQ12),"")) -> 0 | G12: =IF(G$4="","",IFERROR(INDIRECT("'"&G$4&"'!"&$AQ12),"")) -> 0 | H12: =IF(H$4="","",IFERROR(INDIRECT("'"&H$4&"'!"&$AQ12),"")) -> 0 | I12: =IF(I$4="","",IFERROR(INDIRECT("'"&I$4&"'!"&$AQ12),"")) -> 0 | ... AO12: =IF(AO$4="","",IFERROR(INDIRECT("'"&AO$4&"'!"&$AQ12),"")) -> 0 | AQ12: B38
A13: Seuil DSCR critique applicable | B13: =IF(B$4="","",IFERROR(INDIRECT("'"&B$4&"'!"&$AQ13),"")) -> 0 | C13: =IF(C$4="","",IFERROR(INDIRECT("'"&C$4&"'!"&$AQ13),"")) -> 0 | D13: =IF(D$4="","",IFERROR(INDIRECT("'"&D$4&"'!"&$AQ13),"")) -> 0 | E13: =IF(E$4="","",IFERROR(INDIRECT("'"&E$4&"'!"&$AQ13),"")) -> 0 | F13: =IF(F$4="","",IFERROR(INDIRECT("'"&F$4&"'!"&$AQ13),"")) -> 0 | G13: =IF(G$4="","",IFERROR(INDIRECT("'"&G$4&"'!"&$AQ13),"")) -> 0 | H13: =IF(H$4="","",IFERROR(INDIRECT("'"&H$4&"'!"&$AQ13),"")) -> 0 | I13: =IF(I$4="","",IFERROR(INDIRECT("'"&I$4&"'!"&$AQ13),"")) -> 0 | ... AO13: =IF(AO$4="","",IFERROR(INDIRECT("'"&AO$4&"'!"&$AQ13),"")) -> 0 | AQ13: B88
A14: DSCR minimum par échéance | B14: =IF(B$4="","",IFERROR(INDIRECT("'"&B$4&"'!"&$AQ14),"")) -> 0 | C14: =IF(C$4="","",IFERROR(INDIRECT("'"&C$4&"'!"&$AQ14),"")) -> 0 | D14: =IF(D$4="","",IFERROR(INDIRECT("'"&D$4&"'!"&$AQ14),"")) -> 0 | E14: =IF(E$4="","",IFERROR(INDIRECT("'"&E$4&"'!"&$AQ14),"")) -> 0 | F14: =IF(F$4="","",IFERROR(INDIRECT("'"&F$4&"'!"&$AQ14),"")) -> 0 | G14: =IF(G$4="","",IFERROR(INDIRECT("'"&G$4&"'!"&$AQ14),"")) -> 0 | H14: =IF(H$4="","",IFERROR(INDIRECT("'"&H$4&"'!"&$AQ14),"")) -> 0 | I14: =IF(I$4="","",IFERROR(INDIRECT("'"&I$4&"'!"&$AQ14),"")) -> 0 | ... AO14: =IF(AO$4="","",IFERROR(INDIRECT("'"&AO$4&"'!"&$AQ14),"")) -> 0 | AQ14: D154
A15: DSCR minimum sous stress | B15: =IF(B$4="","",IFERROR(INDIRECT("'"&B$4&"'!"&$AQ15),"")) -> 0 | C15: =IF(C$4="","",IFERROR(INDIRECT("'"&C$4&"'!"&$AQ15),"")) -> 0 | D15: =IF(D$4="","",IFERROR(INDIRECT("'"&D$4&"'!"&$AQ15),"")) -> 0 | E15: =IF(E$4="","",IFERROR(INDIRECT("'"&E$4&"'!"&$AQ15),"")) -> 0 | F15: =IF(F$4="","",IFERROR(INDIRECT("'"&F$4&"'!"&$AQ15),"")) -> 0 | G15: =IF(G$4="","",IFERROR(INDIRECT("'"&G$4&"'!"&$AQ15),"")) -> 0 | H15: =IF(H$4="","",IFERROR(INDIRECT("'"&H$4&"'!"&$AQ15),"")) -> 0 | I15: =IF(I$4="","",IFERROR(INDIRECT("'"&I$4&"'!"&$AQ15),"")) -> 0 | ... AO15: =IF(AO$4="","",IFERROR(INDIRECT("'"&AO$4&"'!"&$AQ15),"")) -> 0 | AQ15: D155
A16: DSCR moyen (indicatif) | B16: =IF(B$4="","",IFERROR(INDIRECT("'"&B$4&"'!"&$AQ16),"")) -> 0 | C16: =IF(C$4="","",IFERROR(INDIRECT("'"&C$4&"'!"&$AQ16),"")) -> 0 | D16: =IF(D$4="","",IFERROR(INDIRECT("'"&D$4&"'!"&$AQ16),"")) -> 0 | E16: =IF(E$4="","",IFERROR(INDIRECT("'"&E$4&"'!"&$AQ16),"")) -> 0 | F16: =IF(F$4="","",IFERROR(INDIRECT("'"&F$4&"'!"&$AQ16),"")) -> 0 | G16: =IF(G$4="","",IFERROR(INDIRECT("'"&G$4&"'!"&$AQ16),"")) -> 0 | H16: =IF(H$4="","",IFERROR(INDIRECT("'"&H$4&"'!"&$AQ16),"")) -> 0 | I16: =IF(I$4="","",IFERROR(INDIRECT("'"&I$4&"'!"&$AQ16),"")) -> 0 | ... AO16: =IF(AO$4="","",IFERROR(INDIRECT("'"&AO$4&"'!"&$AQ16),"")) -> 0 | AQ16: D156
... A28: Prochaine saisie | B28: =IF(B$4="","",IFERROR(INDIRECT("'"&B$4&"'!"&$AQ28),"")) -> 0 | C28: =IF(C$4="","",IFERROR(INDIRECT("'"&C$4&"'!"&$AQ28),"")) -> 0 | D28: =IF(D$4="","",IFERROR(INDIRECT("'"&D$4&"'!"&$AQ28),"")) -> 0 | E28: =IF(E$4="","",IFERROR(INDIRECT("'"&E$4&"'!"&$AQ28),"")) -> 0 | F28: =IF(F$4="","",IFERROR(INDIRECT("'"&F$4&"'!"&$AQ28),"")) -> 0 | G28: =IF(G$4="","",IFERROR(INDIRECT("'"&G$4&"'!"&$AQ28),"")) -> 0 | H28: =IF(H$4="","",IFERROR(INDIRECT("'"&H$4&"'!"&$AQ28),"")) -> 0 | I28: =IF(I$4="","",IFERROR(INDIRECT("'"&I$4&"'!"&$AQ28),"")) -> 0 | ... AO28: =IF(AO$4="","",IFERROR(INDIRECT("'"&AO$4&"'!"&$AQ28),"")) -> 0 | AQ28: C4
A30: Les démonstrations à retenir
A31: C3 — Anti-compensation : un score de 73,7 (note 7) ramené à 4 par les plafonds C2 et C3. Un sponsor à 100 et une documentation à 100 ne compensent pas un DSCR de 1,06 sur le creux saisonnier.
A32: C4A et C4B — Le ratio annuel trompe : 1,53 en annuel, 0,59 par échéance. Après sculpture de l'amortissement, apport complémentaire et couverture de change, la note passe de 3 à 6 sans que le marché ait changé.
A33: C5 et AGR — Proportionnalité : le régime simplifié allège la grille de jugement, jamais les plafonds. Un noyau financier à 97 reste plafonné à 6 par la concentration sur un acheteur unique non noté.
A34: TEL, ETH, IMMO — Les plafonds C3, C4, C7, C8 et C9 se déclenchent sur des données, jamais sur une appréciation. MIN — une exclusion X3 empêche toute note, quel que soit le score.

Sheet Fiche comité
A1: Fiche comité — notation Project Finance (modèle V8)
A2: Choisissez le dossier dans la cellule jaune. Tout est lu dans l'onglet du dossier ; imprimez la page ou utilisez « Exporter en PDF ».
A4: Dossier (nom de l'onglet) | B4: C3 | D4: Édité le | E4: =TODAY() -> 0
A6: IDENTIFICATION
A7: Intitulé | B7: =IF($B$4="","",IFERROR(IF(INDIRECT("'"&$B$4&"'!A1")="","",INDIRECT("'"&$B$4&"'!A1")),"")) -> 0
A8: Société de projet — localisation | B8: =IF($B$4="","",IFERROR(IF(INDIRECT("'"&$B$4&"'!A2")="","",INDIRECT("'"&$B$4&"'!A2")),"")) -> 0
A9: Code client T24 | B9: =IF($B$4="","",IFERROR(IF(INDIRECT("'"&$B$4&"'!B15")="","",INDIRECT("'"&$B$4&"'!B15")),"")) -> 0 | C9: Radical | D9: =IF($B$4="","",IFERROR(IF(INDIRECT("'"&$B$4&"'!B16")="","",INDIRECT("'"&$B$4&"'!B16")),"")) -> 0 | E9: Code projet | F9: =IF($B$4="","",IFERROR(IF(INDIRECT("'"&$B$4&"'!B17")="","",INDIRECT("'"&$B$4&"'!B17")),"")) -> 0
A10: Résumé | B10: =IF($B$4="","",IFERROR(IF(INDIRECT("'"&$B$4&"'!A3")="","",INDIRECT("'"&$B$4&"'!A3")),"")) -> 0
A12: NOTATION
A13: NOTE APPROUVÉE (1 à 10) | B13: =IF($B$4="","",IFERROR(IF(INDIRECT("'"&$B$4&"'!B276")="","",INDIRECT("'"&$B$4&"'!B276")),"")) -> 0 | C13: =IF($B$4="","",IFERROR(IF(INDIRECT("'"&$B$4&"'!D6")="","",INDIRECT("'"&$B$4&"'!D6")),"")) -> 0
A14: Statut | B14: =IF($B$4="","",IFERROR(IF(INDIRECT("'"&$B$4&"'!B277")="","",INDIRECT("'"&$B$4&"'!B277")),"")) -> 0
A15: Orientation | B15: =IF($B$4="","",IFERROR(IF(INDIRECT("'"&$B$4&"'!F11")="","",INDIRECT("'"&$B$4&"'!F11")),"")) -> 0
A16: Score global (sur 100) | B16: =IF($B$4="","",IFERROR(IF(INDIRECT("'"&$B$4&"'!B238")="","",INDIRECT("'"&$B$4&"'!B238")),"")) -> 0 | C16: Note calculée | D16: =IF($B$4="","",IFERROR(IF(INDIRECT("'"&$B$4&"'!B239")="","",INDIRECT("'"&$B$4&"'!B239")),"")) -> 0 | E16: Plafond | F16: =IF($B$4="","",IFERROR(IF(INDIRECT("'"&$B$4&"'!F7")="","",INDIRECT("'"&$B$4&"'!F7")),"")) -> 0
A17: Plafonds actifs | B17: =IF($B$4="","",IFERROR(IF(INDIRECT("'"&$B$4&"'!B8")="","",INDIRECT("'"&$B$4&"'!B8")),"")) -> 0
A18: Verrous actifs (X, B) | B18: =IF($B$4="","",IFERROR(IF(INDIRECT("'"&$B$4&"'!B9")="","",INDIRECT("'"&$B$4&"'!B9")),"")) -> 0
A19: Saisies obligatoires manquantes | B19: =IF($B$4="","",IFERROR(IF(INDIRECT("'"&$B$4&"'!B4")="","",INDIRECT("'"&$B$4&"'!B4")),"")) -> 0 | C19: =IF($B$4="","",IFERROR(IF(INDIRECT("'"&$B$4&"'!C4")="","",INDIRECT("'"&$B$4&"'!C4")),"")) -> 0
A21: ROUTAGE ET PROPORTIONNALITÉ
A22: Régime de revenus | B22: =IF($B$4="","",IFERROR(IF(INDIRECT("'"&$B$4&"'!B18")="","",INDIRECT("'"&$B$4&"'!B18")),"")) -> 0 | C22: =IF($B$4="","",IFERROR(IF(INDIRECT("'"&$B$4&"'!C18")="","",INDIRECT("'"&$B$4&"'!C18")),"")) -> 0
A23: Secteur | B23: =IF($B$4="","",IFERROR(IF(INDIRECT("'"&$B$4&"'!B19")="","",INDIRECT("'"&$B$4&"'!B19")),"")) -> 0 | C23: =IF($B$4="","",IFERROR(IF(INDIRECT("'"&$B$4&"'!C19")="","",INDIRECT("'"&$B$4&"'!C19")),"")) -> 0
A24: Phase | B24: =IF($B$4="","",IFERROR(IF(INDIRECT("'"&$B$4&"'!B20")="","",INDIRECT("'"&$B$4&"'!B20")),"")) -> 0 | C24: =IF($B$4="","",IFERROR(IF(INDIRECT("'"&$B$4&"'!C20")="","",INDIRECT("'"&$B$4&"'!C20")),"")) -> 0
A25: Régime de proportionnalité (S / M / L) | B25: =IF($B$4="","",IFERROR(IF(INDIRECT("'"&$B$4&"'!B38")="","",INDIRECT("'"&$B$4&"'!B38")),"")) -> 0 | C25: =IF($B$4="","",IFERROR(IF(INDIRECT("'"&$B$4&"'!C38")="","",INDIRECT("'"&$B$4&"'!C38")),"")) -> 0
A27: INDICATEURS FINANCIERS
A28: Indicateur | B28: Valeur | C28: Repère | D28: Appréciation
A29: DSCR minimum par échéance (retenu) | B29: =IF($B$4="","",IFERROR(IF(INDIRECT("'"&$B$4&"'!D154")="","",INDIRECT("'"&$B$4&"'!D154")),"")) -> 0 | C29: =IF($B$4="","",IFERROR(IF(INDIRECT("'"&$B$4&"'!B88")="","",INDIRECT("'"&$B$4&"'!B88")),"")) -> 0 | D29: =IF($B$4="","",IFERROR(IF(INDIRECT("'"&$B$4&"'!E154")="","",INDIRECT("'"&$B$4&"'!E154")),"")) -> 0
A30: DSCR minimum sous scénario défavorable | B30: =IF($B$4="","",IFERROR(IF(INDIRECT("'"&$B$4&"'!D155")="","",INDIRECT("'"&$B$4&"'!D155")),"")) -> 0 | D30: =IF($B$4="","",IFERROR(IF(INDIRECT("'"&$B$4&"'!E155")="","",INDIRECT("'"&$B$4&"'!E155")),"")) -> 0
A31: DSCR moyen (indicatif) | B31: =IF($B$4="","",IFERROR(IF(INDIRECT("'"&$B$4&"'!D156")="","",INDIRECT("'"&$B$4&"'!D156")),"")) -> 0
A32: DSCR annuel minimum (indicatif) | B32: =IF($B$4="","",IFERROR(IF(INDIRECT("'"&$B$4&"'!D157")="","",INDIRECT("'"&$B$4&"'!D157")),"")) -> 0
A33: Couverture du besoin à terminaison | B33: =IF($B$4="","",IFERROR(IF(INDIRECT("'"&$B$4&"'!B51")="","",INDIRECT("'"&$B$4&"'!B51")),"")) -> 0
A34: Quote-part de dette | B34: =IF($B$4="","",IFERROR(IF(INDIRECT("'"&$B$4&"'!B52")="","",INDIRECT("'"&$B$4&"'!B52")),"")) -> 0 | C34: =P_C9 -> 0
A35: LLCR | B35: =IF($B$4="","",IFERROR(IF(INDIRECT("'"&$B$4&"'!B172")="","",INDIRECT("'"&$B$4&"'!B172")),"")) -> 0 | C35: =P_C4 -> 0
A36: DSRA (mois de service) | B36: =IF($B$4="","",IFERROR(IF(INDIRECT("'"&$B$4&"'!B173")="","",INDIRECT("'"&$B$4&"'!B173")),"")) -> 0 | C36: =P_C7 -> 0
A37: CAPEX du projet (MMAD) | B37: =IF($B$4="","",IFERROR(IF(INDIRECT("'"&$B$4&"'!B25")="","",INDIRECT("'"&$B$4&"'!B25")),"")) -> 0
A38: Exposition de la banque (MMAD) | B38: =IF($B$4="","",IFERROR(IF(INDIRECT("'"&$B$4&"'!B26")="","",INDIRECT("'"&$B$4&"'!B26")),"")) -> 0
A40: CRÉDITS DE LA BANQUE SUR LE PROJET
A41: Numéro du dossier de crédit | B41: Nature | D41: Montant (MMAD) | E41: Devise | F41: Durée (ans)
A42: =IF($B$4="","",IFERROR(IF(INDIRECT("'"&$B$4&"'!A57")="","",INDIRECT("'"&$B$4&"'!A57")),"")) -> 0 | B42: =IF($B$4="","",IFERROR(IF(INDIRECT("'"&$B$4&"'!B57")="","",INDIRECT("'"&$B$4&"'!B57")),"")) -> 0 | D42: =IF($B$4="","",IFERROR(IF(INDIRECT("'"&$B$4&"'!E57")="","",INDIRECT("'"&$B$4&"'!E57")),"")) -> 0 | E42: =IF($B$4="","",IFERROR(IF(INDIRECT("'"&$B$4&"'!F57")="","",INDIRECT("'"&$B$4&"'!F57")),"")) -> 0 | F42: =IF($B$4="","",IFERROR(IF(INDIRECT("'"&$B$4&"'!G57")="","",INDIRECT("'"&$B$4&"'!G57")),"")) -> 0
A43: =IF($B$4="","",IFERROR(IF(INDIRECT("'"&$B$4&"'!A58")="","",INDIRECT("'"&$B$4&"'!A58")),"")) -> 0 | B43: =IF($B$4="","",IFERROR(IF(INDIRECT("'"&$B$4&"'!B58")="","",INDIRECT("'"&$B$4&"'!B58")),"")) -> 0 | D43: =IF($B$4="","",IFERROR(IF(INDIRECT("'"&$B$4&"'!E58")="","",INDIRECT("'"&$B$4&"'!E58")),"")) -> 0 | E43: =IF($B$4="","",IFERROR(IF(INDIRECT("'"&$B$4&"'!F58")="","",INDIRECT("'"&$B$4&"'!F58")),"")) -> 0 | F43: =IF($B$4="","",IFERROR(IF(INDIRECT("'"&$B$4&"'!G58")="","",INDIRECT("'"&$B$4&"'!G58")),"")) -> 0
A44: =IF($B$4="","",IFERROR(IF(INDIRECT("'"&$B$4&"'!A59")="","",INDIRECT("'"&$B$4&"'!A59")),"")) -> 0 | B44: =IF($B$4="","",IFERROR(IF(INDIRECT("'"&$B$4&"'!B59")="","",INDIRECT("'"&$B$4&"'!B59")),"")) -> 0 | D44: =IF($B$4="","",IFERROR(IF(INDIRECT("'"&$B$4&"'!E59")="","",INDIRECT("'"&$B$4&"'!E59")),"")) -> 0 | E44: =IF($B$4="","",IFERROR(IF(INDIRECT("'"&$B$4&"'!F59")="","",INDIRECT("'"&$B$4&"'!F59")),"")) -> 0 | F44: =IF($B$4="","",IFERROR(IF(INDIRECT("'"&$B$4&"'!G59")="","",INDIRECT("'"&$B$4&"'!G59")),"")) -> 0
A45: =IF($B$4="","",IFERROR(IF(INDIRECT("'"&$B$4&"'!A60")="","",INDIRECT("'"&$B$4&"'!A60")),"")) -> 0 | B45: =IF($B$4="","",IFERROR(IF(INDIRECT("'"&$B$4&"'!B60")="","",INDIRECT("'"&$B$4&"'!B60")),"")) -> 0 | D45: =IF($B$4="","",IFERROR(IF(INDIRECT("'"&$B$4&"'!E60")="","",INDIRECT("'"&$B$4&"'!E60")),"")) -> 0 | E45: =IF($B$4="","",IFERROR(IF(INDIRECT("'"&$B$4&"'!F60")="","",INDIRECT("'"&$B$4&"'!F60")),"")) -> 0 | F45: =IF($B$4="","",IFERROR(IF(INDIRECT("'"&$B$4&"'!G60")="","",INDIRECT("'"&$B$4&"'!G60")),"")) -> 0
A46: =IF($B$4="","",IFERROR(IF(INDIRECT("'"&$B$4&"'!A61")="","",INDIRECT("'"&$B$4&"'!A61")),"")) -> 0 | B46: =IF($B$4="","",IFERROR(IF(INDIRECT("'"&$B$4&"'!B61")="","",INDIRECT("'"&$B$4&"'!B61")),"")) -> 0 | D46: =IF($B$4="","",IFERROR(IF(INDIRECT("'"&$B$4&"'!E61")="","",INDIRECT("'"&$B$4&"'!E61")),"")) -> 0 | E46: =IF($B$4="","",IFERROR(IF(INDIRECT("'"&$B$4&"'!F61")="","",INDIRECT("'"&$B$4&"'!F61")),"")) -> 0 | F46: =IF($B$4="","",IFERROR(IF(INDIRECT("'"&$B$4&"'!G61")="","",INDIRECT("'"&$B$4&"'!G61")),"")) -> 0
...

Sheet Comparaison
A1: Comparaison de deux dossiers
A2: Choisissez deux dossiers dans les cellules jaunes : variante de montage, avant et après restructuration, ou deux projets du même secteur. Les écarts significatifs sont surlignés.
A4: Dossiers comparés (noms d'onglet) | B4: C4A | C4: C4B | D4: Écart (B − A)
A6: Indicateur | B6: Dossier A | C6: Dossier B | D6: Écart
A7: Intitulé | B7: =IF($B$4="","",IFERROR(IF(INDIRECT("'"&$B$4&"'!A1")="","",INDIRECT("'"&$B$4&"'!A1")),"")) -> 0 | C7: =IF($C$4="","",IFERROR(IF(INDIRECT("'"&$C$4&"'!A1")="","",INDIRECT("'"&$C$4&"'!A1")),"")) -> 0 | D7: =IF(B7=C7,"=","≠") -> 0
A8: Code projet | B8: =IF($B$4="","",IFERROR(IF(INDIRECT("'"&$B$4&"'!B17")="","",INDIRECT("'"&$B$4&"'!B17")),"")) -> 0 | C8: =IF($C$4="","",IFERROR(IF(INDIRECT("'"&$C$4&"'!B17")="","",INDIRECT("'"&$C$4&"'!B17")),"")) -> 0 | D8: =IF(B8=C8,"=","≠") -> 0
A9: Radical | B9: =IF($B$4="","",IFERROR(IF(INDIRECT("'"&$B$4&"'!B16")="","",INDIRECT("'"&$B$4&"'!B16")),"")) -> 0 | C9: =IF($C$4="","",IFERROR(IF(INDIRECT("'"&$C$4&"'!B16")="","",INDIRECT("'"&$C$4&"'!B16")),"")) -> 0 | D9: =IF(B9=C9,"=","≠") -> 0
A10: Régime de revenus | B10: =IF($B$4="","",IFERROR(IF(INDIRECT("'"&$B$4&"'!B18")="","",INDIRECT("'"&$B$4&"'!B18")),"")) -> 0 | C10: =IF($C$4="","",IFERROR(IF(INDIRECT("'"&$C$4&"'!B18")="","",INDIRECT("'"&$C$4&"'!B18")),"")) -> 0 | D10: =IF(B10=C10,"=","≠") -> 0
A11: Secteur | B11: =IF($B$4="","",IFERROR(IF(INDIRECT("'"&$B$4&"'!B19")="","",INDIRECT("'"&$B$4&"'!B19")),"")) -> 0 | C11: =IF($C$4="","",IFERROR(IF(INDIRECT("'"&$C$4&"'!B19")="","",INDIRECT("'"&$C$4&"'!B19")),"")) -> 0 | D11: =IF(B11=C11,"=","≠") -> 0
A12: Phase | B12: =IF($B$4="","",IFERROR(IF(INDIRECT("'"&$B$4&"'!B20")="","",INDIRECT("'"&$B$4&"'!B20")),"")) -> 0 | C12: =IF($C$4="","",IFERROR(IF(INDIRECT("'"&$C$4&"'!B20")="","",INDIRECT("'"&$C$4&"'!B20")),"")) -> 0 | D12: =IF(B12=C12,"=","≠") -> 0
A13: Régime de proportionnalité | B13: =IF($B$4="","",IFERROR(IF(INDIRECT("'"&$B$4&"'!B38")="","",INDIRECT("'"&$B$4&"'!B38")),"")) -> 0 | C13: =IF($C$4="","",IFERROR(IF(INDIRECT("'"&$C$4&"'!B38")="","",INDIRECT("'"&$C$4&"'!B38")),"")) -> 0 | D13: =IF(B13=C13,"=","≠") -> 0
A14: CAPEX (MMAD) | B14: =IF($B$4="","",IFERROR(IF(INDIRECT("'"&$B$4&"'!B25")="","",INDIRECT("'"&$B$4&"'!B25")),"")) -> 0 | C14: =IF($C$4="","",IFERROR(IF(INDIRECT("'"&$C$4&"'!B25")="","",INDIRECT("'"&$C$4&"'!B25")),"")) -> 0 | D14: =IF(AND(ISNUMBER(B14),ISNUMBER(C14)),C14-B14,IF(B14=C14,"=","≠")) -> 0
A15: Exposition de la banque (MMAD) | B15: =IF($B$4="","",IFERROR(IF(INDIRECT("'"&$B$4&"'!B26")="","",INDIRECT("'"&$B$4&"'!B26")),"")) -> 0 | C15: =IF($C$4="","",IFERROR(IF(INDIRECT("'"&$C$4&"'!B26")="","",INDIRECT("'"&$C$4&"'!B26")),"")) -> 0 | D15: =IF(AND(ISNUMBER(B15),ISNUMBER(C15)),C15-B15,IF(B15=C15,"=","≠")) -> 0
A16: Couverture à terminaison | B16: =IF($B$4="","",IFERROR(IF(INDIRECT("'"&$B$4&"'!B51")="","",INDIRECT("'"&$B$4&"'!B51")),"")) -> 0 | C16: =IF($C$4="","",IFERROR(IF(INDIRECT("'"&$C$4&"'!B51")="","",INDIRECT("'"&$C$4&"'!B51")),"")) -> 0 | D16: =IF(AND(ISNUMBER(B16),ISNUMBER(C16)),C16-B16,IF(B16=C16,"=","≠")) -> 0
A17: Quote-part de dette | B17: =IF($B$4="","",IFERROR(IF(INDIRECT("'"&$B$4&"'!B52")="","",INDIRECT("'"&$B$4&"'!B52")),"")) -> 0 | C17: =IF($C$4="","",IFERROR(IF(INDIRECT("'"&$C$4&"'!B52")="","",INDIRECT("'"&$C$4&"'!B52")),"")) -> 0 | D17: =IF(AND(ISNUMBER(B17),ISNUMBER(C17)),C17-B17,IF(B17=C17,"=","≠")) -> 0
A18: Seuil DSCR critique | B18: =IF($B$4="","",IFERROR(IF(INDIRECT("'"&$B$4&"'!B88")="","",INDIRECT("'"&$B$4&"'!B88")),"")) -> 0 | C18: =IF($C$4="","",IFERROR(IF(INDIRECT("'"&$C$4&"'!B88")="","",INDIRECT("'"&$C$4&"'!B88")),"")) -> 0 | D18: =IF(AND(ISNUMBER(B18),ISNUMBER(C18)),C18-B18,IF(B18=C18,"=","≠")) -> 0
A19: DSCR minimum par échéance | B19: =IF($B$4="","",IFERROR(IF(INDIRECT("'"&$B$4&"'!D154")="","",INDIRECT("'"&$B$4&"'!D154")),"")) -> 0 | C19: =IF($C$4="","",IFERROR(IF(INDIRECT("'"&$C$4&"'!D154")="","",INDIRECT("'"&$C$4&"'!D154")),"")) -> 0 | D19: =IF(AND(ISNUMBER(B19),ISNUMBER(C19)),C19-B19,IF(B19=C19,"=","≠")) -> 0
A20: DSCR minimum sous stress | B20: =IF($B$4="","",IFERROR(IF(INDIRECT("'"&$B$4&"'!D155")="","",INDIRECT("'"&$B$4&"'!D155")),"")) -> 0 | C20: =IF($C$4="","",IFERROR(IF(INDIRECT("'"&$C$4&"'!D155")="","",INDIRECT("'"&$C$4&"'!D155")),"")) -> 0 | D20: =IF(AND(ISNUMBER(B20),ISNUMBER(C20)),C20-B20,IF(B20=C20,"=","≠")) -> 0
A21: DSCR annuel minimum (indicatif) | B21: =IF($B$4="","",IFERROR(IF(INDIRECT("'"&$B$4&"'!D157")="","",INDIRECT("'"&$B$4&"'!D157")),"")) -> 0 | C21: =IF($C$4="","",IFERROR(IF(INDIRECT("'"&$C$4&"'!D157")="","",INDIRECT("'"&$C$4&"'!D157")),"")) -> 0 | D21: =IF(AND(ISNUMBER(B21),ISNUMBER(C21)),C21-B21,IF(B21=C21,"=","≠")) -> 0
A22: LLCR | B22: =IF($B$4="","",IFERROR(IF(INDIRECT("'"&$B$4&"'!B172")="","",INDIRECT("'"&$B$4&"'!B172")),"")) -> 0 | C22: =IF($C$4="","",IFERROR(IF(INDIRECT("'"&$C$4&"'!B172")="","",INDIRECT("'"&$C$4&"'!B172")),"")) -> 0 | D22: =IF(AND(ISNUMBER(B22),ISNUMBER(C22)),C22-B22,IF(B22=C22,"=","≠")) -> 0
A23: DSRA (mois) | B23: =IF($B$4="","",IFERROR(IF(INDIRECT("'"&$B$4&"'!B173")="","",INDIRECT("'"&$B$4&"'!B173")),"")) -> 0 | C23: =IF($C$4="","",IFERROR(IF(INDIRECT("'"&$C$4&"'!B173")="","",INDIRECT("'"&$C$4&"'!B173")),"")) -> 0 | D23: =IF(AND(ISNUMBER(B23),ISNUMBER(C23)),C23-B23,IF(B23=C23,"=","≠")) -> 0
A24: Exposition nette en devises | B24: =IF($B$4="","",IFERROR(IF(INDIRECT("'"&$B$4&"'!B174")="","",INDIRECT("'"&$B$4&"'!B174")),"")) -> 0 | C24: =IF($C$4="","",IFERROR(IF(INDIRECT("'"&$C$4&"'!B174")="","",INDIRECT("'"&$C$4&"'!B174")),"")) -> 0 | D24: =IF(AND(ISNUMBER(B24),ISNUMBER(C24)),C24-B24,IF(B24=C24,"=","≠")) -> 0
A25: Score D1 — Sponsors et actionnariat | B25: =IF($B$4="","",IFERROR(IF(INDIRECT("'"&$B$4&"'!B229")="","",INDIRECT("'"&$B$4&"'!B229")),"")) -> 0 | C25: =IF($C$4="","",IFERROR(IF(INDIRECT("'"&$C$4&"'!B229")="","",INDIRECT("'"&$C$4&"'!B229")),"")) -> 0 | D25: =IF(AND(ISNUMBER(B25),ISNUMBER(C25)),C25-B25,IF(B25=C25,"=","≠")) -> 0
A26: Score D2 — Projet, site, technologie | B26: =IF($B$4="","",IFERROR(IF(INDIRECT("'"&$B$4&"'!B230")="","",INDIRECT("'"&$B$4&"'!B230")),"")) -> 0 | C26: =IF($C$4="","",IFERROR(IF(INDIRECT("'"&$C$4&"'!B230")="","",INDIRECT("'"&$C$4&"'!B230")),"")) -> 0 | D26: =IF(AND(ISNUMBER(B26),ISNUMBER(C26)),C26-B26,IF(B26=C26,"=","≠")) -> 0
A27: Score D3 — Construction et achèvement | B27: =IF($B$4="","",IFERROR(IF(INDIRECT("'"&$B$4&"'!B231")="","",INDIRECT("'"&$B$4&"'!B231")),"")) -> 0 | C27: =IF($C$4="","",IFERROR(IF(INDIRECT("'"&$C$4&"'!B231")="","",INDIRECT("'"&$C$4&"'!B231")),"")) -> 0 | D27: =IF(AND(ISNUMBER(B27),ISNUMBER(C27)),C27-B27,IF(B27=C27,"=","≠")) -> 0
A28: Score D4 — Mécanisme des recettes | B28: =IF($B$4="","",IFERROR(IF(INDIRECT("'"&$B$4&"'!B232")="","",INDIRECT("'"&$B$4&"'!B232")),"")) -> 0 | C28: =IF($C$4="","",IFERROR(IF(INDIRECT("'"&$C$4&"'!B232")="","",INDIRECT("'"&$C$4&"'!B232")),"")) -> 0 | D28: =IF(AND(ISNUMBER(B28),ISNUMBER(C28)),C28-B28,IF(B28=C28,"=","≠")) -> 0
A29: Score D5 — Exploitation et maintenance | B29: =IF($B$4="","",IFERROR(IF(INDIRECT("'"&$B$4&"'!B233")="","",INDIRECT("'"&$B$4&"'!B233")),"")) -> 0 | C29: =IF($C$4="","",IFERROR(IF(INDIRECT("'"&$C$4&"'!B233")="","",INDIRECT("'"&$C$4&"'!B233")),"")) -> 0 | D29: =IF(AND(ISNUMBER(B29),ISNUMBER(C29)),C29-B29,IF(B29=C29,"=","≠")) -> 0
A30: Score D6 — Contreparties et consortium | B30: =IF($B$4="","",IFERROR(IF(INDIRECT("'"&$B$4&"'!B234")="","",INDIRECT("'"&$B$4&"'!B234")),"")) -> 0 | C30: =IF($C$4="","",IFERROR(IF(INDIRECT("'"&$C$4&"'!B234")="","",INDIRECT("'"&$C$4&"'!B234")),"")) -> 0 | D30: =IF(AND(ISNUMBER(B30),ISNUMBER(C30)),C30-B30,IF(B30=C30,"=","≠")) -> 0
A31: Score D7 — Finance et trésorerie (noyau) | B31: =IF($B$4="","",IFERROR(IF(INDIRECT("'"&$B$4&"'!B235")="","",INDIRECT("'"&$B$4&"'!B235")),"")) -> 0 | C31: =IF($C$4="","",IFERROR(IF(INDIRECT("'"&$C$4&"'!B235")="","",INDIRECT("'"&$C$4&"'!B235")),"")) -> 0 | D31: =IF(AND(ISNUMBER(B31),ISNUMBER(C31)),C31-B31,IF(B31=C31,"=","≠")) -> 0
A32: Score D8 — Juridique, sûretés, continuité | B32: =IF($B$4="","",IFERROR(IF(INDIRECT("'"&$B$4&"'!B236")="","",INDIRECT("'"&$B$4&"'!B236")),"")) -> 0 | C32: =IF($C$4="","",IFERROR(IF(INDIRECT("'"&$C$4&"'!B236")="","",INDIRECT("'"&$C$4&"'!B236")),"")) -> 0 | D32: =IF(AND(ISNUMBER(B32),ISNUMBER(C32)),C32-B32,IF(B32=C32,"=","≠")) -> 0
A33: Score D9 — ESG et climat résiduel | B33: =IF($B$4="","",IFERROR(IF(INDIRECT("'"&$B$4&"'!B237")="","",INDIRECT("'"&$B$4&"'!B237")),"")) -> 0 | C33: =IF($C$4="","",IFERROR(IF(INDIRECT("'"&$C$4&"'!B237")="","",INDIRECT("'"&$C$4&"'!B237")),"")) -> 0 | D33: =IF(AND(ISNUMBER(B33),ISNUMBER(C33)),C33-B33,IF(B33=C33,"=","≠")) -> 0
A34: Score global | B34: =IF($B$4="","",IFERROR(IF(INDIRECT("'"&$B$4&"'!B238")="","",INDIRECT("'"&$B$4&"'!B238")),"")) -> 0 | C34: =IF($C$4="","",IFERROR(IF(INDIRECT("'"&$C$4&"'!B238")="","",INDIRECT("'"&$C$4&"'!B238")),"")) -> 0 | D34: =IF(AND(ISNUMBER(B34),ISNUMBER(C34)),C34-B34,IF(B34=C34,"=","≠")) -> 0
A35: Note calculée | B35: =IF($B$4="","",IFERROR(IF(INDIRECT("'"&$B$4&"'!B239")="","",INDIRECT("'"&$B$4&"'!B239")),"")) -> 0 | C35: =IF($C$4="","",IFERROR(IF(INDIRECT("'"&$C$4&"'!B239")="","",INDIRECT("'"&$C$4&"'!B239")),"")) -> 0 | D35: =IF(AND(ISNUMBER(B35),ISNUMBER(C35)),C35-B35,IF(B35=C35,"=","≠")) -> 0
A36: Plafond le plus contraignant | B36: =IF($B$4="","",IFERROR(IF(INDIRECT("'"&$B$4&"'!B273")="","",INDIRECT("'"&$B$4&"'!B273")),"")) -> 0 | C36: =IF($C$4="","",IFERROR(IF(INDIRECT("'"&$C$4&"'!B273")="","",INDIRECT("'"&$C$4&"'!B273")),"")) -> 0 | D36: =IF(AND(ISNUMBER(B36),ISNUMBER(C36)),C36-B36,IF(B36=C36,"=","≠")) -> 0
A37: NOTE APPROUVÉE | B37: =IF($B$4="","",IFERROR(IF(INDIRECT("'"&$B$4&"'!B276")="","",INDIRECT("'"&$B$4&"'!B276")),"")) -> 0 | C37: =IF($C$4="","",IFERROR(IF(INDIRECT("'"&$C$4&"'!B276")="","",INDIRECT("'"&$C$4&"'!B276")),"")) -> 0 | D37: =IF(AND(ISNUMBER(B37),ISNUMBER(C37)),C37-B37,IF(B37=C37,"=","≠")) -> 0
A38: Statut | B38: =IF($B$4="","",IFERROR(IF(INDIRECT("'"&$B$4&"'!B277")="","",INDIRECT("'"&$B$4&"'!B277")),"")) -> 0 | C38: =IF($C$4="","",IFERROR(IF(INDIRECT("'"&$C$4&"'!B277")="","",INDIRECT("'"&$C$4&"'!B277")),"")) -> 0 | D38: =IF(B38=C38,"=","≠") -> 0
A39: Plafonds actifs | B39: =IF($B$4="","",IFERROR(IF(INDIRECT("'"&$B$4&"'!B8")="","",INDIRECT("'"&$B$4&"'!B8")),"")) -> 0 | C39: =IF($C$4="","",IFERROR(IF(INDIRECT("'"&$C$4&"'!B8")="","",INDIRECT("'"&$C$4&"'!B8")),"")) -> 0 | D39: =IF(B39=C39,"=","≠") -> 0
A40: Verrous actifs | B40: =IF($B$4="","",IFERROR(IF(INDIRECT("'"&$B$4&"'!B9")="","",INDIRECT("'"&$B$4&"'!B9")),"")) -> 0 | C40: =IF($C$4="","",IFERROR(IF(INDIRECT("'"&$C$4&"'!B9")="","",INDIRECT("'"&$C$4&"'!B9")),"")) -> 0 | D40: =IF(B40=C40,"=","≠") -> 0
A41: Avis risques | B41: =IF($B$4="","",IFERROR(IF(INDIRECT("'"&$B$4&"'!B285")="","",INDIRECT("'"&$B$4&"'!B285")),"")) -> 0 | C41: =IF($C$4="","",IFERROR(IF(INDIRECT("'"&$C$4&"'!B285")="","",INDIRECT("'"&$C$4&"'!B285")),"")) -> 0 | D41: =IF(B41=C41,"=","≠") -> 0
A42: Saisies obligatoires manquantes | B42: =IF($B$4="","",IFERROR(IF(INDIRECT("'"&$B$4&"'!B4")="","",INDIRECT("'"&$B$4&"'!B4")),"")) -> 0 | C42: =IF($C$4="","",IFERROR(IF(INDIRECT("'"&$C$4&"'!B4")="","",INDIRECT("'"&$C$4&"'!B4")),"")) -> 0 | D42: =IF(AND(ISNUMBER(B42),ISNUMBER(C42)),C42-B42,IF(B42=C42,"=","≠")) -> 0

Sheet C1
A1: CAS 1 · Centrale solaire photovoltaïque 80 MWc | J1: DOSSIER_V8 | K1: V3
A2: SPV « Solaris Drâa » SA (fictive) — Région de Drâa-Tafilalet
A3: Centrale PV vendant sa production à l'acheteur public national sous contrat d'achat de 25 ans à quantité garantie et tarif indexé. Financement en dirhams, EPC clé-en-main forfaitaire.
A4: À SAISIR (cellules orange) | B4: =COUNTIF($R$14:$R$63,0) -> 0 | C4: =IF(B4=0,"Saisie complète : lisez la note ci-dessous, puis « Fiche comité ».","Prochaine saisie : "&INDEX($P$14:$P$63,MATCH(0,$R$14:$R$63,0))) -> 0 | G4: =IF(B4=0,"",HYPERLINK("#"&INDEX($Q$14:$Q$63,MATCH(0,$R$14:$R$63,0)),"→ Aller à la cellule "&INDEX($Q$14:$Q$63,MATCH(0,$R$14:$R$63,0)))) -> 0
A5: ="TABLEAU DE BORD — "&IF($B$17="","code projet à saisir",$B$17)&" · client "&IF($B$15="","—",$B$15)&" · radical "&IF($B$16="","—",$B$16) -> 0
A6: NOTE APPROUVÉE (1 à 10) | B6: =B276 -> 0 | C6: Libellé | D6: =IFERROR(INDEX(P_ConvLib,MATCH(B276,P_ConvNote,0)),"") -> 0 | E6: Statut | F6: =B277 -> 0
A7: Score global (sur 100) | B7: =B238 -> 0 | C7: Note calculée | D7: =B239 -> 0 | E7: Plafond applicable | F7: =IF(B273>=10,"Aucun (10)",B273) -> 0
A8: Plafonds actifs | B8: =IF(TRIM(IF(E258="Oui","C1 ("&F258&") ","")&IF(E259="Oui","C2 ("&F259&") ","")&IF(E260="Oui","C3 ("&F260&") ","")&IF(E261="Oui","C4 ("&F261&") ","")&IF(E262="Oui","C5 ("&F262&") ","")&IF(E263="Oui","C6 ("&F263&") ","")&IF(E264="Oui","C7 ("&F264&") ","")&IF(E265="Oui","C8 ("&F265&") ","")&IF(E266="Oui","C9 ("&F266&") ","")&IF(E267="Oui","C10 ("&F267&") ","")&IF(E268="Oui","C11 ("&F268&") ","")&IF(E269="Oui","C12 ("&F269&") ","")&IF(E270="Oui","C13 ("&F270&") ","")&IF(E271="Oui","C14 ("&F271&") ","")&IF(E272="Oui","C15 ("&F272&") ",""))="","Aucun",TRIM(IF(E258="Oui","C1 ("&F258&") ","")&IF(E259="Oui","C2 ("&F259&") ","")&IF(E260="Oui","C3 ("&F260&") ","")&IF(E261="Oui","C4 ("&F261&") ","")&IF(E262="Oui","C5 ("&F262&") ","")&IF(E263="Oui","C6 ("&F263&") ","")&IF(E264="Oui","C7 ("&F264&") ","")&IF(E265="Oui","C8 ("&F265&") ","")&IF(E266="Oui","C9 ("&F266&") ","")&IF(E267="Oui","C10 ("&F267&") ","")&IF(E268="Oui","C11 ("&F268&") ","")&IF(E269="Oui","C12 ("&F269&") ","")&IF(E270="Oui","C13 ("&F270&") ","")&IF(E271="Oui","C14 ("&F271&") ","")&IF(E272="Oui","C15 ("&F272&") ","")))&IF(COUNTIF(E258:E272,"n.r.")>0," — "&COUNTIF(E258:E272,"n.r.")&" plafond(s) non évalué(s) faute de donnée","") -> 0
A9: Verrous actifs (exclusions X, blocages B) | B9: =IF(TRIM(IF(F243="Oui","X1 ","")&IF(F244="Oui","X2 ","")&IF(F245="Oui","X3 ","")&IF(F246="Oui","X4 ","")&IF(F247="Oui","B1 ","")&IF(F248="Oui","B2 ","")&IF(F249="Oui","B3 ","")&IF(F250="Oui","B4 ","")&IF(F251="Oui","B5 ","")&IF(F252="Oui","B6 ","")&IF(F253="Oui","B7 ","")&IF(F254="Oui","B8 ",""))="","Aucun",TRIM(IF(F243="Oui","X1 ","")&IF(F244="Oui","X2 ","")&IF(F245="Oui","X3 ","")&IF(F246="Oui","X4 ","")&IF(F247="Oui","B1 ","")&IF(F248="Oui","B2 ","")&IF(F249="Oui","B3 ","")&IF(F250="Oui","B4 ","")&IF(F251="Oui","B5 ","")&IF(F252="Oui","B6 ","")&IF(F253="Oui","B7 ","")&IF(F254="Oui","B8 ",""))) -> 0
A10: Régime de proportionnalité retenu | B10: =B38 -> 0 | C10: DSCR minimum | D10: =D154 -> 0 | E10: DSCR stressé min. | F10: =D155 -> 0
A11: Complétude (noyau N1-N6 et grille) | B11: =B225 -> 0 | C11: Noyau financier D7 | D11: =D169 -> 0 | E11: Orientation | F11: =IFERROR(INDEX(P_ConvOrient,MATCH(B276,P_ConvNote,0)),"") -> 0
A12: Aller à la section : | B12: =HYPERLINK("#A13","1 · Identification") -> 0 | C12: =HYPERLINK("#A40","3 · Sources") -> 0 | D12: =HYPERLINK("#A90","6 · Échéancier") -> 0 | E12: =HYPERLINK("#A161","7 · Noyau") -> 0 | F12: =HYPERLINK("#A188","8 · Grille") -> 0 | G12: =HYPERLINK("#A256","11 · Plafonds") -> 0 | H12: =HYPERLINK("#A279","13 · Commentaires") -> 0
A13: 1 · IDENTIFICATION ET ROUTAGE — codes du client et du projet ; le routage pilote seuils et poids
A14: Axe | B14: Valeur | C14: Libellé, contrôle | P14: 1 · Code client T24 | Q14: B15 | R14: =IF(AND(LEN(TRIM($B$15))>=1,LEN($B$15)<=20),1,0) -> 0
A15: Code client T24 (société de projet) | B15: 20041027 | C15: =IF(B15="","À saisir — Texte, zéros de tête conservés.",IF(AND(LEN(TRIM(B15))>=1,LEN(B15)<=20),"Format conforme.","Format non conforme : Texte, zéros de tête conservés.")) -> 0 | P15: 1 · Radical du client (7 chiffres) | Q15: B16 | R15: =IF(AND(LEN($B$16)=7,SUMPRODUCT(--ISNUMBER(FIND(MID($B$16,ROW(INDIRECT("1:7"))+0,1),"0123456789")))=7),1,0) -> 0
A16: Radical du client (7 chiffres) | B16: 0041027 | C16: =IF(B16="","À saisir — Exactement 7 chiffres, zéros de tête compris.",IF(AND(LEN(B16)=7,SUMPRODUCT(--ISNUMBER(FIND(MID(B16,ROW(INDIRECT("1:7"))+0,1),"0123456789")))=7),"Format conforme.","Format non conforme : Exactement 7 chiffres, zéros de tête compris.")) -> 0 | P16: 1 · Code projet (PF-AAAA-NNNN) | Q16: B17 | R16: =IF(AND(LEN($B$17)=12,EXACT(LEFT($B$17,3),"PF-"),MID($B$17,8,1)="-",SUMPRODUCT(--ISNUMBER(FIND(MID($B$17,ROW(INDIRECT("1:4"))+3,1),"0123456789")))=4,SUMPRODUCT(--ISNUMBER(FIND(MID($B$17,ROW(INDIRECT("1:4"))+8,1),"0123456789")))=4),1,0) -> 0
A17: Code projet | B17: PF-2026-0001 | C17: =IF(B17="","À saisir — Format PF-AAAA-NNNN.",IF(AND(LEN(B17)=12,EXACT(LEFT(B17,3),"PF-"),MID(B17,8,1)="-",SUMPRODUCT(--ISNUMBER(FIND(MID(B17,ROW(INDIRECT("1:4"))+3,1),"0123456789")))=4,SUMPRODUCT(--ISNUMBER(FIND(MID(B17,ROW(INDIRECT("1:4"))+8,1),"0123456789")))=4),"Format conforme.","Format non conforme : Format PF-AAAA-NNNN.")) -> 0 | P17: 1 · Régime de revenus | Q17: B18 | R17: =IF($B$18<>"",1,0) -> 0
A18: C — Régime de revenus | B18: R1 | C18: =IFERROR(INDEX(P_RegLib,MATCH(B18,P_Regimes,0)),"") -> 0 | P18: 1 · Secteur du projet | Q18: B19 | R18: =IF($B$19<>"",1,0) -> 0
A19: D — Secteur du projet | B19: ENR | C19: =IFERROR(INDEX(P_SecLib,MATCH(B19,P_SecCodes,0)),"") -> 0 | P19: 1 · Phase du projet | Q19: B20 | R19: =IF($B$20<>"",1,0) -> 0
A20: B — Phase | B20: P1 | C20: =IFERROR(INDEX(P_PhaseLib,MATCH(B20,P_PhaseCodes,0)),"") -> 0 | P20: 1 · Périodicité des échéances | Q20: B21 | R20: =IF($B$21<>"",1,0) -> 0
A21: Périodicité du service de la dette | B21: Semestrielle | C21: Jamais annuelle : le DSCR se mesure échéance par échéance. | P21: 2 · Exposition de la banque (MMAD) | Q21: B26 | R21: =IF(ISNUMBER($B$26),1,0) -> 0
A22: A — Famille de financement | B22: PF-FLUX | C22: SPV dédiée, remboursement par les flux du projet (R5 vente d'actifs : hors outil). | P22: 2 · Recettes, coûts et dette en dirhams ? | Q22: B27 | R22: =IF($B$27<>"",1,0) -> 0
P23: 2 · Durée du financement (ans) | Q23: B28 | R23: =IF(ISNUMBER($B$28),1,0) -> 0
A24: 2 · RÉGIME DE PROPORTIONNALITÉ — calculé, jamais choisi | P24: 2 · Technologie éprouvée ? | Q24: B29 | R24: =IF($B$29<>"",1,0) -> 0
A25: CAPEX du projet économique complet (MMAD) | B25: =B50 -> 0 | C25: Repris du total des emplois (section 3). | P25: 2 · EPC clé-en-main de moins de 18 mois ? (phase P1) | Q25: B30 | R25: =IF(OR(NOT($B$20="P1"),$B$30<>""),1,0) -> 0
A26: Exposition de la banque (MMAD) | B26: 465 | P26: 2 · Acheteur principal unique ? | Q26: B31 | R26: =IF($B$31<>"",1,0) -> 0
A27: Recettes, coûts et dette intégralement en dirhams | B27: Oui | P27: 2 · Première référence technologique ? | Q27: B32 | R27: =IF($B$32<>"",1,0) -> 0
A28: Durée du financement (ans) | B28: 20 | P28: 2 · Opération consortiale ? | Q28: B33 | R28: =IF($B$33<>"",1,0) -> 0
A29: Technologie : ≥ 3 références industrielles de plus de 3 ans | B29: Oui | P29: 2 · Contrat de revenus de plus de 20 ans ? | Q29: B34 | R29: =IF($B$34<>"",1,0) -> 0
A30: En P1 : EPC clé-en-main forfaitaire, prix et délai garantis, < 18 mois | B30: Non | P30: 2 · Site à risque climatique élevé ? | Q30: B35 | R30: =IF($B$35<>"",1,0) -> 0
A31: Acheteur principal unique et identifié | B31: Oui | P31: 2 · Nombre de contreparties clés | Q31: B36 | R31: =IF(ISNUMBER($B$36),1,0) -> 0
A32: Technologie constituant une première référence dans la juridiction | B32: Non | P32: 3 · Emplois : montants du besoin à terminaison | Q32: B42 | R32: =IF(N($B$50)>0,1,0) -> 0
A33: Opération consortiale relevant de la directive 3/W/2025 | B33: Non | P33: 3 · Ressources engagées : montants | Q33: E42 | R33: =IF(N($E$50)>0,1,0) -> 0
A34: Concession ou contrat de revenus de plus de 20 ans | B34: Oui | P34: 3 · Nature de chaque ressource | Q34: F42 | R34: =IF(SUMPRODUCT(ISNUMBER($E$42:$E$49)*($F$42:$F$49=""))=0,1,0) -> 0
A35: Site classé à risque climatique physique élevé | B35: Non | P35: 3 · Plan de remédiation (couverture entre 95 et 100 %) | Q35: B53 | R35: =IF(OR(NOT(AND($B$20="P1",ISNUMBER($B$51),N($B$51)>=P_N3_V,N($B$51)<P_N3_F)),$B$53<>""),1,0) -> 0
A36: Nombre de contreparties clés | B36: 3 | P36: 6 · Choc du scénario défavorable (%) | Q36: B91 | R36: =IF(ISNUMBER($B$91),1,0) -> 0
A37: Régime calculé (avant escalade) | B37: =IF(OR(B25="",B25=0,B18=""),"",IF(OR(B25>P_L_CAPEX,N(B26)>P_L_EXPO,B18="R4",B32="Oui",N(B174)>0,B33="Oui",B34="Oui",B35="Oui",N(B36)>P_L_NBCP),"L",IF(AND(B25<=P_S_CAPEX,B26<>"",N(B26)<=P_S_EXPO,OR(B18="R1",B18="R2"),B29="Oui",B27="Oui",B28<>"",N(B28)<=P_S_DUREE,OR(B20<>"P1",B30="Oui"),B31="Oui",COUNTIF($F$243:$F$254,"Oui")=0),"S","M"))) -> 0 | C37: =IF(B37="","",IF(B37="L","Escalade : "&IF(B25>P_L_CAPEX,"CAPEX > "&P_L_CAPEX&" MMAD ; ","")&IF(N(B26)>P_L_EXPO,"exposition > "&P_L_EXPO&" MMAD ; ","")&IF(B18="R4","régime de revenus R4 ; ","")&IF(B32="Oui","première référence technologique ; ","")&IF(N(B174)>0,"devises non intégralement couvertes ; ","")&IF(B33="Oui","opération consortiale ; ","")&IF(B34="Oui","contrat de revenus > 20 ans ; ","")&IF(B35="Oui","risque climatique élevé ; ","")&IF(N(B36)>P_L_NBCP,"plus de "&P_L_NBCP&" contreparties clés ; ",""),IF(B37="S","Toutes les conditions du régime simplifié sont réunies.","Régime standard par défaut : une condition du régime S manque, aucune condition d'escalade."))) -> 0 | P37: 6 · Échéancier : CFADS d'au moins deux périodes | Q37: B93 | R37: =IF(COUNT($B$93:$B$152)>=2,1,0) -> 0
A38: RÉGIME RETENU (après escalade automatique) | B38: =IF(B37="","",IF(AND(IF(AND(B37="S",COUNTIF($F$243:$F$254,"Oui")>0),"M",B37)="M",COUNTIF($E$258:$E$272,"Oui")>0),"L",IF(AND(B37="S",COUNTIF($F$243:$F$254,"Oui")>0),"M",B37))) -> 0 | C38: =IF(B38=B37,"Aucune escalade.",IF(B38="L","Escalade : un plafond de note est actif (M passe en L).","Escalade : un verrou est actif (S passe en M).")) -> 0 | P38: 6 · Service de la dette de chaque période | Q38: C93 | R38: =IF(SUMPRODUCT(ISNUMBER($B$93:$B$152)*(1-ISNUMBER($C$93:$C$152)))=0,1,0) -> 0
P39: 7 · N4 — Liquidité : situation à choisir | Q39: E166 | R39: =IF($B$166<>"",1,0) -> 0
A40: 3 · SOURCES ET EMPLOIS (MMAD) — test de financement à terminaison ; crédits de la banque | P40: 7 · N5 — Levier : situation à choisir | Q40: E167 | R40: =IF($B$167<>"",1,0) -> 0
...

Sheet C2
A1: CAS 2 · Usine de dessalement 100 000 m³/jour | J1: DOSSIER_V8 | K1: V3
A2: SPV « Aqua Souss » SA (fictive) — Littoral de Souss-Massa
A3: Usine d'osmose inverse rémunérée par une redevance de capacité versée par l'acheteur public, assortie d'une redevance variable répercutant le coût de l'énergie dans une limite plafonnée.
A4: À SAISIR (cellules orange) | B4: =COUNTIF($R$14:$R$63,0) -> 0 | C4: =IF(B4=0,"Saisie complète : lisez la note ci-dessous, puis « Fiche comité ».","Prochaine saisie : "&INDEX($P$14:$P$63,MATCH(0,$R$14:$R$63,0))) -> 0 | G4: =IF(B4=0,"",HYPERLINK("#"&INDEX($Q$14:$Q$63,MATCH(0,$R$14:$R$63,0)),"→ Aller à la cellule "&INDEX($Q$14:$Q$63,MATCH(0,$R$14:$R$63,0)))) -> 0
A5: ="TABLEAU DE BORD — "&IF($B$17="","code projet à saisir",$B$17)&" · client "&IF($B$15="","—",$B$15)&" · radical "&IF($B$16="","—",$B$16) -> 0
A6: NOTE APPROUVÉE (1 à 10) | B6: =B276 -> 0 | C6: Libellé | D6: =IFERROR(INDEX(P_ConvLib,MATCH(B276,P_ConvNote,0)),"") -> 0 | E6: Statut | F6: =B277 -> 0
A7: Score global (sur 100) | B7: =B238 -> 0 | C7: Note calculée | D7: =B239 -> 0 | E7: Plafond applicable | F7: =IF(B273>=10,"Aucun (10)",B273) -> 0
A8: Plafonds actifs | B8: =IF(TRIM(IF(E258="Oui","C1 ("&F258&") ","")&IF(E259="Oui","C2 ("&F259&") ","")&IF(E260="Oui","C3 ("&F260&") ","")&IF(E261="Oui","C4 ("&F261&") ","")&IF(E262="Oui","C5 ("&F262&") ","")&IF(E263="Oui","C6 ("&F263&") ","")&IF(E264="Oui","C7 ("&F264&") ","")&IF(E265="Oui","C8 ("&F265&") ","")&IF(E266="Oui","C9 ("&F266&") ","")&IF(E267="Oui","C10 ("&F267&") ","")&IF(E268="Oui","C11 ("&F268&") ","")&IF(E269="Oui","C12 ("&F269&") ","")&IF(E270="Oui","C13 ("&F270&") ","")&IF(E271="Oui","C14 ("&F271&") ","")&IF(E272="Oui","C15 ("&F272&") ",""))="","Aucun",TRIM(IF(E258="Oui","C1 ("&F258&") ","")&IF(E259="Oui","C2 ("&F259&") ","")&IF(E260="Oui","C3 ("&F260&") ","")&IF(E261="Oui","C4 ("&F261&") ","")&IF(E262="Oui","C5 ("&F262&") ","")&IF(E263="Oui","C6 ("&F263&") ","")&IF(E264="Oui","C7 ("&F264&") ","")&IF(E265="Oui","C8 ("&F265&") ","")&IF(E266="Oui","C9 ("&F266&") ","")&IF(E267="Oui","C10 ("&F267&") ","")&IF(E268="Oui","C11 ("&F268&") ","")&IF(E269="Oui","C12 ("&F269&") ","")&IF(E270="Oui","C13 ("&F270&") ","")&IF(E271="Oui","C14 ("&F271&") ","")&IF(E272="Oui","C15 ("&F272&") ","")))&IF(COUNTIF(E258:E272,"n.r.")>0," — "&COUNTIF(E258:E272,"n.r.")&" plafond(s) non évalué(s) faute de donnée","") -> 0
A9: Verrous actifs (exclusions X, blocages B) | B9: =IF(TRIM(IF(F243="Oui","X1 ","")&IF(F244="Oui","X2 ","")&IF(F245="Oui","X3 ","")&IF(F246="Oui","X4 ","")&IF(F247="Oui","B1 ","")&IF(F248="Oui","B2 ","")&IF(F249="Oui","B3 ","")&IF(F250="Oui","B4 ","")&IF(F251="Oui","B5 ","")&IF(F252="Oui","B6 ","")&IF(F253="Oui","B7 ","")&IF(F254="Oui","B8 ",""))="","Aucun",TRIM(IF(F243="Oui","X1 ","")&IF(F244="Oui","X2 ","")&IF(F245="Oui","X3 ","")&IF(F246="Oui","X4 ","")&IF(F247="Oui","B1 ","")&IF(F248="Oui","B2 ","")&IF(F249="Oui","B3 ","")&IF(F250="Oui","B4 ","")&IF(F251="Oui","B5 ","")&IF(F252="Oui","B6 ","")&IF(F253="Oui","B7 ","")&IF(F254="Oui","B8 ",""))) -> 0
A10: Régime de proportionnalité retenu | B10: =B38 -> 0 | C10: DSCR minimum | D10: =D154 -> 0 | E10: DSCR stressé min. | F10: =D155 -> 0
A11: Complétude (noyau N1-N6 et grille) | B11: =B225 -> 0 | C11: Noyau financier D7 | D11: =D169 -> 0 | E11: Orientation | F11: =IFERROR(INDEX(P_ConvOrient,MATCH(B276,P_ConvNote,0)),"") -> 0
A12: Aller à la section : | B12: =HYPERLINK("#A13","1 · Identification") -> 0 | C12: =HYPERLINK("#A40","3 · Sources") -> 0 | D12: =HYPERLINK("#A90","6 · Échéancier") -> 0 | E12: =HYPERLINK("#A161","7 · Noyau") -> 0 | F12: =HYPERLINK("#A188","8 · Grille") -> 0 | G12: =HYPERLINK("#A256","11 · Plafonds") -> 0 | H12: =HYPERLINK("#A279","13 · Commentaires") -> 0
